Workbook
Name a: '[1]QUOTATION BREAKDOWN (2)'!#REF!
Name contract: '01 PEK-001 Pen Eak'!#REF!
Name contract: '02 JPP-001 งานชัยนาท'!#REF!
Name contract: '03 TG-002 เปลี่ยน ACB'!#REF!
Name contract: '04 PKE-001 ติดตั้งลากสาย RASA1'!#REF!
Name contract: '05 QMP-001งาน PM 315kVA'!#REF!
Name contract: '06 UNT-001 รพ.ภัทรเวช'!#REF!
Name contract: '07 SUT-001 บ้านห้วยขวาง'!#REF!
Name contract: '08 PKE-002 ติดตั้งพัดลมระบายอาก'!#REF!
Name contract: '09 JEP-2601-001'!#REF!
Name contract: '10 UNT-2601-001 รพ.ภัทรเวช (2)'!#REF!
Name contract: '11 TMD-2601-001'!#REF!
Name contract: '12 TMD-2601-002'!#REF!
Name contract: '13 JPP-2601-001'!#REF!
Name contract: '14 TMD-2601-003'!#REF!
Name contract: '15 RACH36'!#REF!
Name contract: '20 SOL-264 02'!#REF!
Name contract: '21 TMD-004'!#REF!
Name contract: '22 TMD-005'!#REF!
Name contract: '23 TMD-006'!#REF!
Name contract: '24 POM-007'!#REF!
Name contract: 'MC-002 Udonthani'!#REF!
Name contract: 'PC-004 อาคาร D'!#REF!
Name contract: 'PC-005 SHIN FONG'!#REF!
Name contract: 'PC-006 JOWLE'!#REF!
Name contract: 'PC-007 บ้านลาดกระบัง'!#REF!
Name contract: 'PC-008 JINHAI'!#REF!
Name contract: 'PC-009 BHP'!#REF!
Name contract: 'PPC-001 Nestle'!#REF!
Name contract: 'XP-001 งานนครนายก'!#REF!
Name contract: ค่าใช้จ่ายออฟฟิศ!#REF!
Name contract: '[2]CMS REV1'!$L$3
Name customs: #REF!
Name di: #REF!
Name disc: #REF!
Name DISCOUNT: #REF!
Name equip: #REF!
Name In: '[1]QUOTATION BREAKDOWN (2)'!#REF!
Name k: [3]offer!$N$7
Name kk: [3]offer!$N$6
Name material: #REF!
Name Pro: #REF!
Name span: #REF!
Name stock: #REF!

Sheet JPP Code 
A2: No. | B2: Description | D2: Code
A4: 1 | B4: 10 | C4: MATERIALS | D4: 10
A5: 2 | B5: 20 | C5: SUB CONTRACTOR | D5: 20
A6: 3 | B6: 30 | C6: HEAVY EQUIPMENT | D6: 30
A7: 4 | B7: 40 | C7: RENTAL | D7: 40
A8: 5 | B8: 50 | C8: STAFF EXPENSE (Salary) | D8: 50
A9: 6 | B9: 60 | C9: OFFICE EXPENSE | D9: 60
A10: 7 | B10: 70 | C10: ENTERTAIN | D10: 70
A11: 8 | B11: 80 | C11: MISCELLANEOUS | D11: 80
A13: Code ทางด้านบัญชี (ในอนาคต)

Sheet Money forecast
C1: วันที่เงินจะเข้า
A2: 1 | B2: เงินสดย่อย | C2: 46152 | D2: 15000 | E2: 20000 | H2: =SUM(D2:G2) -> 35000
A3: 2 | B3: เบิกเงินงานสระบุรี | C3: 46157 | D3: 90164.83 | H3: =SUM(D3:G3) -> 90164.83
A4: 3 | H4: =SUM(D4:G4) -> 0
A5: 4 | H5: =SUM(D5:G5) -> 0
A6: 5 | H6: =SUM(D6:G6) -> 0
A7: 6 | H7: =SUM(D7:G7) -> 0
A8: 7 | H8: =SUM(D8:G8) -> 0
A9: 8 | B9: เงินเบิกเมเดนชา | C9: 46192 | D9: 20000 | E9: 36000 | F9: 12795 | H9: =SUM(D9:G9) -> 68795
G11: ยอดรวม | H11: =SUM(H2:H10) -> 193959.83
G12: กระแสเงินสด

Sheet Project Onhand
A2: Item No. | B2: Job No. | C2: Client Name | D2: Work Description | E2: Contract Price | F2: Start Date | G2: Finish Date | H2: % Complete | I2: Profit | K2: Invoice Oct 2025 | N2: % | O2: 46082 | P2: % | Q2: 46113 | R2: % | S2: 46143 | T2: % | U2: 46174 | V2: % | W2: 46204 | X2: % | Y2: 46235 | Z2: % | AA2: 46266 | AB2: % | AC2: 46296 | AD2: % | AE2: 46327 | AF2: % | AG2: 46357 | AH2: % | AI2: 46388 | AJ2: % | AK2: 46419 | AL2: % | AM2: 46447 | AN2: % | AO2: 46478
O3: =SUM(O4:O19) -> 740100.93 | Q3: =SUM(Q4:Q19) -> 873629.6 | S3: =SUM(S4:S19) -> 593927.47 | U3: =SUM(U4:U19) -> 85000 | W3: =SUM(W4:W19) -> 85000 | Y3: =SUM(Y4:Y19) -> 0 | AA3: =SUM(AA4:AA19) -> 0 | AC3: =SUM(AC4:AC19) -> 0 | AE3: =SUM(AE4:AE19) -> 0 | AG3: =SUM(AG4:AG19) -> 0 | AI3: =SUM(AI4:AI19) -> 0 | AK3: =SUM(AK4:AK19) -> 0 | AM3: =SUM(AM4:AM19) -> 0 | AO3: =SUM(AO4:AO19) -> 0
A4: 1 | C4: TMD | D4: งานติดตั้งระบบไฟฟ้า ระบบแจ้งเตือนเพลิงไหม้ Depot ORL MWS | E4: 610770 | F4: 46082 | G4: 46122 | H4: 0.8 | I4: 0.9 | J4: =I4*C4 -> #VALUE! | K4: 0.9 | L4: =K4*E4 -> 549693 | N4: 0.5 | O4: =N4*E4 -> 305385 | P4: 0.4 | Q4: =P4*$E$4 -> 244308 | R4: 0.1 | S4: =R4*$E$4 -> 61077 | U4: =T4*$E$4 -> 0 | W4: =V4*$E$4 -> 0 | Y4: =X4*$E$4 -> 0 | AA4: =Z4*$E$4 -> 0 | AC4: =AB4*$E$4 -> 0 | AE4: =AD4*$E$4 -> 0 | AG4: =AF4*$E$4 -> 0 | AI4: =AH4*$E$4 -> 0 | AK4: =AJ4*$E$4 -> 0 | AM4: =AL4*$E$4 -> 0 | AO4: =AN4*$E$4 -> 0
A5: 2 | C5: PK-ESS | D5: งาน Turnkey งานติดตั้งระบบไฟฟ้า UPS โรงพยาบาลการไฟฟ้าสามเสน | E5: 850000 | F5: 46101 | G5: 46172 | H5: 0.1 | I5: 0.3 | J5: =I5*C5 -> #VALUE! | K5: 0.3 | L5: =K5*E5 -> 255000 | O5: =N5*$E$5 -> 0 | P5: 0.3 | Q5: =P5*$E$5 -> 255000 | R5: 0.5 | S5: =R5*$E$5 -> 425000 | T5: 0.1 | U5: =T5*$E$5 -> 85000 | V5: 0.1 | W5: =V5*$E$5 -> 85000 | Y5: =X5*$E$5 -> 0 | AA5: =Z5*$E$5 -> 0 | AC5: =AB5*$E$5 -> 0 | AE5: =AD5*$E$5 -> 0 | AG5: =AF5*$E$5 -> 0 | AI5: =AH5*$E$5 -> 0 | AK5: =AJ5*$E$5 -> 0 | AM5: =AL5*$E$5 -> 0 | AO5: =AN5*$E$5 -> 0
A6: 3 | C6: Khun Ma | D6: งานติดตั้งระบบโซล่าร์เซลล์ บนหลังคา 10kW + Battery 21kW | E6: 400000 | F6: 46118 | G6: 46118 | H6: 1 | I6: 1 | J6: =I6*C6 -> #VALUE! | K6: 1 | L6: =K6*E6 -> 400000 | N6: 0.5 | O6: =N6*$E$6 -> 200000 | P6: 0.5 | Q6: =P6*$E$6 -> 200000 | S6: =R6*$E$6 -> 0 | U6: =T6*$E$6 -> 0 | W6: =V6*$E$6 -> 0 | Y6: =X6*$E$6 -> 0 | AA6: =Z6*$E$6 -> 0 | AC6: =AB6*$E$6 -> 0 | AE6: =AD6*$E$6 -> 0 | AG6: =AF6*$E$6 -> 0 | AI6: =AH6*$E$6 -> 0 | AK6: =AJ6*$E$6 -> 0 | AM6: =AL6*$E$6 -> 0 | AO6: =AN6*$E$6 -> 0
A7: 4 | C7: Khun Ken | D7: งานเพิ่มแบตเตอรี่สำหรับโซล่าร์เซลล์บ้าน | E7: 220000 | F7: 46108 | G7: 46132 | H7: 0 | I7: 1 | J7: =I7*C7 -> #VALUE! | K7: 1 | L7: =K7*E7 -> 220000 | N7: 0.5 | O7: 112149.53 | R7: 0.5 | S7: =E7-O7 -> 107850.47 | U7: =T7*$E$7 -> 0 | W7: =V7*$E$7 -> 0 | Y7: =X7*$E$7 -> 0 | AA7: =Z7*$E$7 -> 0 | AC7: =AB7*$E$7 -> 0 | AE7: =AD7*$E$7 -> 0 | AG7: =AF7*$E$7 -> 0 | AI7: =AH7*$E$7 -> 0 | AK7: =AJ7*$E$7 -> 0 | AM7: =AL7*$E$7 -> 0 | AO7: =AN7*$E$7 -> 0
A8: 5 | C8: Khun Koson | D8: งานติดตั้งระบบโซล่าร์เซลล์ บนหลังคา 17.68kW | E8: 235000 | F8: 46108 | G8: 46132 | H8: 1 | I8: 1 | J8: =I8*C8 -> #VALUE! | K8: 1 | L8: =K8*E8 -> 235000 | N8: 0.5 | O8: =N8*$E$7 -> 110000 | P8: 0.5 | Q8: 125000 | S8: =R8*$E$7 -> 0 | U8: =T8*$E$7 -> 0 | W8: =V8*$E$7 -> 0 | Y8: =X8*$E$7 -> 0 | AA8: =Z8*$E$7 -> 0 | AC8: =AB8*$E$7 -> 0 | AE8: =AD8*$E$7 -> 0 | AG8: =AF8*$E$7 -> 0 | AI8: =AH8*$E$7 -> 0 | AK8: =AJ8*$E$7 -> 0 | AM8: =AL8*$E$7 -> 0 | AO8: =AN8*$E$7 -> 0
A9: 6 | C9: กฤชณรงค์ธัญกิจ | D9: งานเปลี่ยนหางปลา สาย SAC 95 | E9: 41888 | F9: 46108 | G9: 46108 | H9: 1 | I9: 1 | J9: =I9*C9 -> #VALUE! | K9: 1 | L9: =K9*E9 -> 41888 | N9: 0.3 | O9: =N9*$E$9 -> 12566.4 | P9: 0.7 | Q9: =E9-O9 -> 29321.6 | S9: =R9*$E$9 -> 0 | U9: =T9*$E$9 -> 0 | W9: =V9*$E$9 -> 0 | Y9: =X9*$E$9 -> 0 | AA9: =Z9*$E$9 -> 0 | AC9: =AB9*$E$9 -> 0 | AE9: =AD9*$E$9 -> 0 | AG9: =AF9*$E$9 -> 0 | AI9: =AH9*$E$9 -> 0 | AK9: =AJ9*$E$9 -> 0 | AM9: =AL9*$E$9 -> 0 | AO9: =AN9*$E$9 -> 0
A10: 7 | C10: TMD | D10: งานติดตั้งระบบไฟฟ้า Dangerous Waste - General Waste | E10: 339693.72 | F10: 46082 | G10: 46122 | H10: 0.5 | I10: 0.2 | J10: =I10*C10 -> #VALUE! | K10: 0.2 | L10: =K10*E10 -> 67938.744 | O10: =N10*$E$11 -> 0 | P10: 0.2 | Q10: =P10*$E$11 -> 20000 | R10: 0 | S10: =R10*$E$11 -> 0 | U10: =T10*$E$11 -> 0 | W10: =V10*$E$11 -> 0 | Y10: =X10*$E$11 -> 0 | AA10: =Z10*$E$11 -> 0 | AC10: =AB10*$E$11 -> 0 | AE10: =AD10*$E$11 -> 0 | AG10: =AF10*$E$11 -> 0 | AI10: =AH10*$E$11 -> 0 | AK10: =AJ10*$E$11 -> 0 | AM10: =AL10*$E$11 -> 0 | AO10: =AN10*$E$11 -> 0
A11: 8 | C11: TMD | D11: งานติดตั้งระบบไฟฟ้า Dangerous Goods | E11: 100000 | F11: 46082 | G11: 46122 | H11: 0 | I11: 0 | J11: =I11*C11 -> #VALUE! | K11: 0 | L11: =K11*E11 -> 0 | O11: =N11*$E$11 -> 0 | Q11: =P11*$E$11 -> 0 | R11: 0 | S11: =R11*$E$11 -> 0 | U11: =T11*$E$11 -> 0 | W11: =V11*$E$11 -> 0 | Y11: =X11*$E$11 -> 0 | AA11: =Z11*$E$11 -> 0 | AC11: =AB11*$E$11 -> 0 | AE11: =AD11*$E$11 -> 0 | AG11: =AF11*$E$11 -> 0 | AI11: =AH11*$E$11 -> 0 | AK11: =AJ11*$E$11 -> 0 | AM11: =AL11*$E$11 -> 0 | AO11: =AN11*$E$11 -> 0
A12: 9 | C12: วังสระปทุม | D12: งานติดตั้งโซล่าร์เซลล์ 10kW | E12: 874000 | F12: 46148 | G12: 46203 | H12: 0 | J12: =I12*C12 -> #VALUE! | L12: =K12*E12 -> 0 | O12: =N12*$E$12 -> 0 | Q12: =P12*$E$12 -> 0 | S12: =R12*$E$12 -> 0 | U12: =T12*$E$12 -> 0 | W12: =V12*$E$12 -> 0 | Y12: =X12*$E$12 -> 0 | AA12: =Z12*$E$12 -> 0 | AC12: =AB12*$E$12 -> 0 | AE12: =AD12*$E$12 -> 0 | AG12: =AF12*$E$12 -> 0 | AI12: =AH12*$E$12 -> 0 | AK12: =AJ12*$E$12 -> 0 | AM12: =AL12*$E$12 -> 0 | AO12: =AN12*$E$12 -> 0
A13: 10 | C13: บ้านคุณเม | D13: งานติดตั้งโซล่าร์เซลล์ 5kW | E13: 122000 | F13: 46148 | G13: 46203 | H13: 0 | J13: =I13*C13 -> #VALUE! | L13: =K13*E13 -> 0 | O13: =N13*$E$12 -> 0 | Q13: =P13*$E$12 -> 0 | S13: =R13*$E$12 -> 0 | U13: =T13*$E$12 -> 0 | W13: =V13*$E$12 -> 0 | Y13: =X13*$E$12 -> 0 | AA13: =Z13*$E$12 -> 0 | AC13: =AB13*$E$12 -> 0 | AE13: =AD13*$E$12 -> 0 | AG13: =AF13*$E$12 -> 0 | AI13: =AH13*$E$12 -> 0 | AK13: =AJ13*$E$12 -> 0 | AM13: =AL13*$E$12 -> 0 | AO13: =AN13*$E$12 -> 0
A14: 11 | J14: =I14*C14 -> 0 | L14: =K14*E14 -> 0 | O14: =N14*$E$12 -> 0 | Q14: =P14*$E$12 -> 0 | S14: =R14*$E$12 -> 0 | U14: =T14*$E$12 -> 0 | W14: =V14*$E$12 -> 0 | Y14: =X14*$E$12 -> 0 | AA14: =Z14*$E$12 -> 0 | AC14: =AB14*$E$12 -> 0 | AE14: =AD14*$E$12 -> 0 | AG14: =AF14*$E$12 -> 0 | AI14: =AH14*$E$12 -> 0 | AK14: =AJ14*$E$12 -> 0 | AM14: =AL14*$E$12 -> 0 | AO14: =AN14*$E$12 -> 0
A15: 12 | J15: =I15*C15 -> 0 | L15: =K15*E15 -> 0 | O15: =N15*$E$12 -> 0 | Q15: =P15*$E$12 -> 0 | S15: =R15*$E$12 -> 0 | U15: =T15*$E$12 -> 0 | W15: =V15*$E$12 -> 0 | Y15: =X15*$E$12 -> 0 | AA15: =Z15*$E$12 -> 0 | AC15: =AB15*$E$12 -> 0 | AE15: =AD15*$E$12 -> 0 | AG15: =AF15*$E$12 -> 0 | AI15: =AH15*$E$12 -> 0 | AK15: =AJ15*$E$12 -> 0 | AM15: =AL15*$E$12 -> 0 | AO15: =AN15*$E$12 -> 0
A16: 13 | J16: =I16*C16 -> 0 | L16: =K16*E16 -> 0 | O16: =N16*$E$12 -> 0 | Q16: =P16*$E$12 -> 0 | S16: =R16*$E$12 -> 0 | U16: =T16*$E$12 -> 0 | W16: =V16*$E$12 -> 0 | Y16: =X16*$E$12 -> 0 | AA16: =Z16*$E$12 -> 0 | AC16: =AB16*$E$12 -> 0 | AE16: =AD16*$E$12 -> 0 | AG16: =AF16*$E$12 -> 0 | AI16: =AH16*$E$12 -> 0 | AK16: =AJ16*$E$12 -> 0 | AM16: =AL16*$E$12 -> 0 | AO16: =AN16*$E$12 -> 0
A17: 14 | J17: =I17*C17 -> 0 | L17: =K17*E17 -> 0 | O17: =N17*$E$12 -> 0 | Q17: =P17*$E$12 -> 0 | S17: =R17*$E$12 -> 0 | U17: =T17*$E$12 -> 0 | W17: =V17*$E$12 -> 0 | Y17: =X17*$E$12 -> 0 | AA17: =Z17*$E$12 -> 0 | AC17: =AB17*$E$12 -> 0 | AE17: =AD17*$E$12 -> 0 | AG17: =AF17*$E$12 -> 0 | AI17: =AH17*$E$12 -> 0 | AK17: =AJ17*$E$12 -> 0 | AM17: =AL17*$E$12 -> 0 | AO17: =AN17*$E$12 -> 0
A18: 15 | J18: =I18*C18 -> 0 | L18: =K18*E18 -> 0 | O18: =N18*$E$18 -> 0 | Q18: =P18*$E$18 -> 0 | S18: =R18*$E$18 -> 0 | U18: =T18*$E$18 -> 0 | W18: =V18*$E$18 -> 0 | Y18: =X18*$E$18 -> 0 | AA18: =Z18*$E$18 -> 0 | AC18: =AB18*$E$18 -> 0 | AE18: =AD18*$E$18 -> 0 | AG18: =AF18*$E$18 -> 0 | AI18: =AH18*$E$18 -> 0 | AK18: =AJ18*$E$18 -> 0 | AM18: =AL18*$E$18 -> 0 | AO18: =AN18*$E$18 -> 0
A19: 16 | J19: =I19*C19 -> 0 | L19: =K19*E19 -> 0 | O19: =N19*$E$19 -> 0 | Q19: =P19*$E$19 -> 0 | S19: =R19*$E$19 -> 0 | U19: =T19*$E$19 -> 0 | W19: =V19*$E$19 -> 0 | Y19: =X19*$E$19 -> 0 | AA19: =Z19*$E$19 -> 0 | AC19: =AB19*$E$19 -> 0 | AE19: =AD19*$E$19 -> 0 | AG19: =AF19*$E$19 -> 0 | AI19: =AH19*$E$19 -> 0 | AK19: =AJ19*$E$19 -> 0 | AM19: =AL19*$E$19 -> 0 | AO19: =AN19*$E$19 -> 0
E20: =SUM(E4:E19) -> 3793351.7 | J20: =SUM(J4:J19) -> #VALUE! | L20: =SUM(L4:L19) -> 1769519.7 | O20: =SUM(O4:O19) -> 740100.93 | Q20: =Q8+Q6+Q5 -> 580000
M21: ค่าใช้จ่าย | O21: =SUM(O22:O34) -> 501799.22 | Q21: =SUM(Q22:Q32) -> 1000113.8
G22: เงินสด | H22: 342422.65 | J22: 299904 | L22: 299904 | M22: รัชดา 36 | N22: 0.7 | O22: =L22*0.7 -> 209932.8 | P22: บ้านเคน | Q22: =230050*0.7 -> 161035
J23: 85000 | L23: 85000 | M23: Aof | N23: 0.5 | O23: =L23*0.5 -> 42500 | P23: Aof | Q23: 43000
H24: =H22-O21 -> -159376.57 | M24: เงินเดือน | O24: 130000 | P24: ออฟฟิศ&เงินเดือน | Q24: 150000
J25: 157888.08 | L25: 157888.08 | M25: Overwash | N25: 0.3 | O25: =L25*0.3 -> 47366.424 | P25: APT | Q25: =480000*0.15 -> 72000
J26: 480000 | L26: 480000 | M26: อั๋น | N26: 0.15 | O26: =N26*L26 -> 72000 | P26: ท่อ | Q26: 44344.55
P27: APT | Q27: 49920
P28: APT | Q28: 124800
P29: GTI | Q29: =809.78+1318.24+118258.17+224628.1 -> 345014.29
P30: ค่าพุกและสตัด | Q30: 10000
P33: ยอดที่ค้างจ่าย | Q33: =Q25+Q24+Q22+Q30 -> 393035
P34: ยอดเก็บเงิน | Q34: =Q7+Q4+Q9 -> 273629.6

Sheet PC-009 BHP
B1: Factory/Company | C1: PROCHAIN | H1: Start Date | I1: 45833
B2: Project Name | C2: BHP Factory | H2: Sale Up Date
B3: Job Code. | C3: =C52 -> 0
B4: Quotation No. | E4: PROJECT BUDGET RECORD | H4: INVOICE (%) | I4: 0 | AA4: 45811 | AB4: 45812 | AC4: 45813 | AD4: 45814 | AE4: 45815 | AF4: 45816 | AG4: 45817 | AH4: 45818 | AI4: 45819 | AJ4: 45820 | AK4: 45821 | AL4: 45822 | AM4: 45823 | AN4: 45824 | AO4: 45825 | AP4: 45826 | AQ4: 45827 | AR4: 45828 | AS4: 45829 | AT4: 45830 | AU4: 45831 | AV4: 45832 | AW4: 45833 | AX4: 45834 | AY4: 45835 | AZ4: 45836 | BA4: 45837 | BB4: 45838 | BE4: 45839 | BF4: 45840 | BG4: 45841 | BH4: 45842 | BI4: 45843 | BJ4: 45844 | BK4: 45845 | BL4: 45846 | BM4: 45847 | BN4: 45848 | BO4: 45849 | BP4: 45850 | BQ4: 45851 | BR4: 45852 | BS4: 45853 | BT4: 45854 | BU4: 45855 | BV4: 45856 | BW4: 45857
B5: Contract Price | C5: =C53 -> 0
B6: Budget Price | C6: =F64 -> 6880000 | Z6: 100
B7: PROFIT | C7: =(C5-C6)/C5 -> #DIV/0! | D7: ACTUAL | E7: 1 | U7: No. | V7: Name | W7: Salary | X7: S per Day | Y7: ค่าโทรศัพท์ | Z7: ค่าอื่นๆ | AA7: =SUM(AA8:AA31) -> 4 | AB7: =SUM(AB8:AB31) -> 3 | AC7: =SUM(AC8:AC31) -> 3 | AD7: =SUM(AD8:AD31) -> 3 | AE7: =SUM(AE8:AE31) -> 3 | AF7: =SUM(AF8:AF31) -> 0 | AG7: =SUM(AG8:AG31) -> 11 | AH7: =SUM(AH8:AH31) -> 11 | ... BB7: =SUM(BB8:BB31) -> 0 | BE7: =SUM(BE8:BE31) -> 0 | BF7: =SUM(BF8:BF31) -> 0 | BG7: =SUM(BG8:BG31) -> 0 | BH7: =SUM(BH8:BH31) -> 0 | BI7: =SUM(BI8:BI31) -> 0 | BJ7: =SUM(BJ8:BJ31) -> 0 | BK7: =SUM(BK8:BK31) -> 0 | BL7: =SUM(BL8:BL31) -> 0 | ... BW7: =SUM(BW8:BW31) -> 0
B8: No. | C8: Vendor Name | D8: Material Number | E8: Description | F8: Text/Quo.No. | G8: Amount | H8: Updated By | I8: Date | J8: PO | U8: 1 | V8: พี่เอ็ก | W8: 31500 | X8: 1050 | Y8: 1400 | AG8: 1 | AH8: 1 | AI8: 1 | AJ8: 1 | AK8: 1 | AL8: 1 | AN8: 1 | AO8: 1 | AP8: 1 | AQ8: 1 | AR8: 1 | AS8: 1 | AU8: 1 | AV8: 1 | BC8: =SUM(AA8:BB8) -> 14 | BD8: =(BC8*X8)+Y8+Z8 -> 16100
U9: 2 | V9: เอลฟ์ | W9: 21300 | X9: 710 | Y9: 1400 | Z9: 2000 | AA9: 1 | AG9: 1 | AH9: 1 | AI9: 1 | AJ9: 1 | AK9: 1 | AL9: 1 | AN9: 1 | AO9: 1 | AP9: 1 | AQ9: 1 | AR9: 1 | AS9: 1 | AU9: 1 | AV9: 1 | BC9: =SUM(AA9:BB9) -> 15 | BD9: =(BC9*X9)+Y9+Z9 -> 14050
B10: 1 | C10: ค่าดำเนินการติดตั้งมิเตอร์การไฟฟ้า | D10: 80 | E10: ค่าดำเนินการ | G10: 15000 | H10: K.Kowit | I10: 45858 | U10: 3 | V10: เฮียนิ้ง | W10: 18500 | X10: 616.66667 | Z10: =$Z$6*BC11 -> 1400 | BC10: =SUM(AA10:BB10) -> 0 | BD10: =(BC10*X10)+Y10+Z10 -> 1400
B11: 2 | U11: 4 | V11: หนึ่ง | W11: 15000 | X11: 500 | Z11: =$Z$6*BC12 -> 1400 | AG11: 1 | AH11: 1 | AI11: 1 | AJ11: 1 | AK11: 1 | AL11: 1 | AN11: 1 | AO11: 1 | AP11: 1 | AQ11: 1 | AR11: 1 | AS11: 1 | AU11: 1 | AV11: 1 | BC11: =SUM(AA11:BB11) -> 14 | BD11: =(BC11*X11)+Y11+Z11 -> 8400
B12: 3 | U12: 5 | V12: แอล | W12: 14000 | X12: 466.66667 | Z12: =$Z$6*BC13 -> 0 | AG12: 1 | AH12: 1 | AI12: 1 | AJ12: 1 | AK12: 1 | AL12: 1 | AN12: 1 | AO12: 1 | AP12: 1 | AQ12: 1 | AR12: 1 | AS12: 1 | AU12: 1 | AV12: 1 | BC12: =SUM(AA12:BB12) -> 14 | BD12: =(BC12*X12)+Y12+Z12 -> 6533.3333
B13: 4 | U13: 6 | V13: เวฟ | W13: 14000 | X13: 466.66667 | Z13: =$Z$6*BC14 -> 0 | BC13: =SUM(AA13:BB13) -> 0 | BD13: =(BC13*X13)+Y13+Z13 -> 0
B14: 5 | U14: 78 | V14: บาส | W14: 13000 | X14: 433.33333 | Z14: =$Z$6*BC15 -> 0 | BC14: =SUM(AA14:BB14) -> 0 | BD14: =(BC14*X14)+Y14+Z14 -> 0
B15: 6 | U15: 8 | V15: พี่มิ้ว(แอดมิน) | W15: 14000 | X15: 466.66667 | Z15: =$Z$6*BC16 -> 0 | BC15: =SUM(AA15:BB15) -> 0 | BD15: =(BC15*X15)+Y15+Z15 -> 0
B16: 7 | U16: 9 | V16: พี่ดี๋ | W16: 50000 | X16: 1666.6667 | Z16: =$Z$6*BC17 -> 1400 | BC16: =SUM(AA16:BB16) -> 0 | BD16: =(BC16*X16)+Y16+Z16 -> 1400
B17: 8 | U17: 10 | V17: พี่เจมส์ | W17: 17000 | X17: 566.66667 | Z17: =$Z$6*BC18 -> 0 | AG17: 1 | AH17: 1 | AI17: 1 | AJ17: 1 | AK17: 1 | AL17: 1 | AN17: 1 | AO17: 1 | AP17: 1 | AQ17: 1 | AR17: 1 | AS17: 1 | AU17: 1 | AV17: 1 | BC17: =SUM(AA17:BB17) -> 14 | BD17: =(BC17*X17)+Y17+Z17 -> 7933.3333
B18: 9 | U18: 11 | V18: อั้ม | W18: 20000 | X18: 666.66667 | Z18: =$Z$6*BC19 -> 1400 | BC18: =SUM(AA18:BB18) -> 0 | BD18: =(BC18*X18)+Y18+Z18 -> 1400
B19: 10 | U19: 12 | V19: พี่เต้ย (รายวัน) | W19: 4950 | X19: 450 | Z19: =$Z$6*BC20 -> 0 | AG19: 1 | AH19: 1 | AI19: 1 | AJ19: 1 | AK19: 1 | AL19: 1 | AN19: 1 | AO19: 1 | AP19: 1 | AQ19: 1 | AR19: 1 | AS19: 1 | AU19: 1 | AV19: 1 | BC19: =SUM(AA19:BB19) -> 14 | BD19: =(BC19*X19)+Y19+Z19 -> 6300
B20: 11 | U20: 13 | V20: จิว(ฝึกงาน) | W20: 3300 | X20: 300 | Z20: =$Z$6*BC21 -> 0 | BC20: =SUM(AA20:BB20) -> 0 | BD20: =(BC20*X20)+Y20+Z20 -> 0
B21: 12 | U21: 14 | V21: บอล(ฝึกงาน300) | W21: 3300 | X21: 300 | Z21: =$Z$6*BC22 -> 0 | BC21: =SUM(AA21:BB21) -> 0 | BD21: =(BC21*X21)+Y21+Z21 -> 0
B22: 13 | U22: 15 | V22: มุก(ฝึกงาน) | W22: 3300 | X22: 300 | Z22: =$Z$6*BC23 -> 0 | BC22: =SUM(AA22:BB22) -> 0 | BD22: =(BC22*X22)+Y22+Z22 -> 0
B23: 14 | U23: 16 | V23: เบนซ์(ฝึกงาน300) | W23: 3300 | X23: 300 | Z23: =$Z$6*BC24 -> 1900 | BC23: =SUM(AA23:BB23) -> 0 | BD23: =(BC23*X23)+Y23+Z23 -> 1900
B24: 15 | U24: 17 | V24: เต๋า(ฝึกงาน) | W24: 2700 | X24: 300 | Z24: =$Z$6*BC25 -> 1900 | AA24: 1 | AB24: 1 | AC24: 1 | AD24: 1 | AE24: 1 | AG24: 1 | AH24: 1 | AI24: 1 | AJ24: 1 | AK24: 1 | AL24: 1 | AN24: 1 | AO24: 1 | AP24: 1 | AQ24: 1 | AR24: 1 | AS24: 1 | AU24: 1 | AV24: 1 | BC24: =SUM(AA24:BB24) -> 19 | BD24: =(BC24*X24)+Y24+Z24 -> 7600
B25: 16 | U25: 18 | V25: เฟียส(ฝึกงาน) | W25: 2200 | X25: 200 | Z25: =$Z$6*BC26 -> 1900 | AA25: 1 | AB25: 1 | AC25: 1 | AD25: 1 | AE25: 1 | AG25: 1 | AH25: 1 | AI25: 1 | AJ25: 1 | AK25: 1 | AL25: 1 | AN25: 1 | AO25: 1 | AP25: 1 | AQ25: 1 | AR25: 1 | AS25: 1 | AU25: 1 | AV25: 1 | BC25: =SUM(AA25:BB25) -> 19 | BD25: =(BC25*X25)+Y25+Z25 -> 5700
B26: 17 | U26: 19 | V26: ฟลุ๊ค(ฝึกงาน) | W26: 1440 | X26: 180 | Z26: =$Z$6*BC27 -> 0 | AA26: 1 | AB26: 1 | AC26: 1 | AD26: 1 | AE26: 1 | AG26: 1 | AH26: 1 | AI26: 1 | AJ26: 1 | AK26: 1 | AL26: 1 | AN26: 1 | AO26: 1 | AP26: 1 | AQ26: 1 | AR26: 1 | AS26: 1 | AU26: 1 | AV26: 1 | BC26: =SUM(AA26:BB26) -> 19 | BD26: =(BC26*X26)+Y26+Z26 -> 3420
B27: 18 | U27: 20 | V27: เจมส์(ฝึกงาน) | W27: 2160 | X27: 180 | Z27: =$Z$6*BC28 -> 1400 | BC27: =SUM(AA27:BB27) -> 0 | BD27: =(BC27*X27)+Y27+Z27 -> 1400
B28: 19 | U28: 21 | V28: นาย(ฝึกงาน) | W28: 1980 | X28: 180 | Z28: =$Z$6*BC29 -> 0 | AG28: 1 | AH28: 1 | AI28: 1 | AJ28: 1 | AK28: 1 | AL28: 1 | AN28: 1 | AO28: 1 | AP28: 1 | AQ28: 1 | AR28: 1 | AS28: 1 | AU28: 1 | AV28: 1 | BC28: =SUM(AA28:BB28) -> 14 | BD28: =(BC28*X28)+Y28+Z28 -> 2520
B29: 20 | U29: 22 | V29: ดิว(ฝึกงาน) | W29: 1440 | X29: 180 | Z29: =$Z$6*BC30 -> 0 | BC29: =SUM(AA29:BB29) -> 0 | BD29: =(BC29*X29)+Y29+Z29 -> 0
B30: 21 | U30: 23 | V30: น็อต(ฝึกงาน) | W30: 2160 | X30: 180 | Z30: =$Z$6*BC31 -> 1400 | BC30: =SUM(AA30:BB30) -> 0 | BD30: =(BC30*X30)+Y30+Z30 -> 1400
B31: 22 | U31: 24 | V31: อาม(ฝึกงาน) | W31: 1980 | X31: 180 | Z31: =$Z$6*BC32 -> 0 | AG31: 1 | AH31: 1 | AI31: 1 | AJ31: 1 | AK31: 1 | AL31: 1 | AN31: 1 | AO31: 1 | AP31: 1 | AQ31: 1 | AR31: 1 | AS31: 1 | AU31: 1 | AV31: 1 | BC31: =SUM(AA31:BB31) -> 14 | BD31: =(BC31*X31)+Y31+Z31 -> 2520
B32: 23 | BD32: =SUM(BD8:BD31) -> 89976.667
B33: 24
B34: 25
B35: 26
B36: 27
B37: 28
B38: 29
B39: 30
B40: 31
...

Sheet PC-008 JINHAI
B1: Factory/Company | C1: PROCHAIN | H1: Start Date | I1: 45833
B2: Project Name | C2: JINHAI Factory | H2: Sale Up Date
B3: Job Code. | C3: =C52 -> TMD-2601/001
B4: Quotation No. | E4: PROJECT BUDGET RECORD | H4: INVOICE (%) | I4: 0 | AA4: 45811 | AB4: 45812 | AC4: 45813 | AD4: 45814 | AE4: 45815 | AF4: 45816 | AG4: 45817 | AH4: 45818 | AI4: 45819 | AJ4: 45820 | AK4: 45821 | AL4: 45822 | AM4: 45823 | AN4: 45824 | AO4: 45825 | AP4: 45826 | AQ4: 45827 | AR4: 45828 | AS4: 45829 | AT4: 45830 | AU4: 45831 | AV4: 45832 | AW4: 45833 | AX4: 45834 | AY4: 45835 | AZ4: 45836 | BA4: 45837 | BB4: 45838 | BE4: 45839 | BF4: 45840 | BG4: 45841 | BH4: 45842 | BI4: 45843 | BJ4: 45844 | BK4: 45845 | BL4: 45846 | BM4: 45847 | BN4: 45848 | BO4: 45849 | BP4: 45850 | BQ4: 45851 | BR4: 45852 | BS4: 45853 | BT4: 45854 | BU4: 45855 | BV4: 45856 | BW4: 45857
B5: Contract Price | C5: =C53 -> 42000
B6: Budget Price | C6: =F64 -> 10090000 | Z6: 100
B7: PROFIT | C7: =(C5-C6)/C5 -> -239.2381 | D7: ACTUAL | E7: 1 | U7: No. | V7: Name | W7: Salary | X7: S per Day | Y7: ค่าโทรศัพท์ | Z7: ค่าอื่นๆ | AA7: =SUM(AA8:AA31) -> 4 | AB7: =SUM(AB8:AB31) -> 3 | AC7: =SUM(AC8:AC31) -> 3 | AD7: =SUM(AD8:AD31) -> 3 | AE7: =SUM(AE8:AE31) -> 3 | AF7: =SUM(AF8:AF31) -> 0 | AG7: =SUM(AG8:AG31) -> 11 | AH7: =SUM(AH8:AH31) -> 11 | ... BB7: =SUM(BB8:BB31) -> 0 | BE7: =SUM(BE8:BE31) -> 0 | BF7: =SUM(BF8:BF31) -> 0 | BG7: =SUM(BG8:BG31) -> 0 | BH7: =SUM(BH8:BH31) -> 0 | BI7: =SUM(BI8:BI31) -> 0 | BJ7: =SUM(BJ8:BJ31) -> 0 | BK7: =SUM(BK8:BK31) -> 0 | BL7: =SUM(BL8:BL31) -> 0 | ... BW7: =SUM(BW8:BW31) -> 0
B8: No. | C8: Vendor Name | D8: Material Number | E8: Description | F8: Text/Quo.No. | G8: Amount | H8: Updated By | I8: Date | J8: PO | U8: 1 | V8: พี่เอ็ก | W8: 31500 | X8: 1050 | Y8: 1400 | AG8: 1 | AH8: 1 | AI8: 1 | AJ8: 1 | AK8: 1 | AL8: 1 | AN8: 1 | AO8: 1 | AP8: 1 | AQ8: 1 | AR8: 1 | AS8: 1 | AU8: 1 | AV8: 1 | BC8: =SUM(AA8:BB8) -> 14 | BD8: =(BC8*X8)+Y8+Z8 -> 16100
U9: 2 | V9: เอลฟ์ | W9: 21300 | X9: 710 | Y9: 1400 | Z9: 2000 | AA9: 1 | AG9: 1 | AH9: 1 | AI9: 1 | AJ9: 1 | AK9: 1 | AL9: 1 | AN9: 1 | AO9: 1 | AP9: 1 | AQ9: 1 | AR9: 1 | AS9: 1 | AU9: 1 | AV9: 1 | BC9: =SUM(AA9:BB9) -> 15 | BD9: =(BC9*X9)+Y9+Z9 -> 14050
B10: 1 | C10: ค่าดำเนินการติดตั้งมิเตอร์การไฟฟ้า | D10: 80 | E10: ค่าดำเนินการ | G10: 15000 | H10: K.Kowit | I10: 45858 | U10: 3 | V10: เฮียนิ้ง | W10: 18500 | X10: 616.66667 | Z10: =$Z$6*BC11 -> 1400 | BC10: =SUM(AA10:BB10) -> 0 | BD10: =(BC10*X10)+Y10+Z10 -> 1400
B11: 2 | U11: 4 | V11: หนึ่ง | W11: 15000 | X11: 500 | Z11: =$Z$6*BC12 -> 1400 | AG11: 1 | AH11: 1 | AI11: 1 | AJ11: 1 | AK11: 1 | AL11: 1 | AN11: 1 | AO11: 1 | AP11: 1 | AQ11: 1 | AR11: 1 | AS11: 1 | AU11: 1 | AV11: 1 | BC11: =SUM(AA11:BB11) -> 14 | BD11: =(BC11*X11)+Y11+Z11 -> 8400
B12: 3 | U12: 5 | V12: แอล | W12: 14000 | X12: 466.66667 | Z12: =$Z$6*BC13 -> 0 | AG12: 1 | AH12: 1 | AI12: 1 | AJ12: 1 | AK12: 1 | AL12: 1 | AN12: 1 | AO12: 1 | AP12: 1 | AQ12: 1 | AR12: 1 | AS12: 1 | AU12: 1 | AV12: 1 | BC12: =SUM(AA12:BB12) -> 14 | BD12: =(BC12*X12)+Y12+Z12 -> 6533.3333
B13: 4 | U13: 6 | V13: เวฟ | W13: 14000 | X13: 466.66667 | Z13: =$Z$6*BC14 -> 0 | BC13: =SUM(AA13:BB13) -> 0 | BD13: =(BC13*X13)+Y13+Z13 -> 0
B14: 5 | U14: 78 | V14: บาส | W14: 13000 | X14: 433.33333 | Z14: =$Z$6*BC15 -> 0 | BC14: =SUM(AA14:BB14) -> 0 | BD14: =(BC14*X14)+Y14+Z14 -> 0
B15: 6 | U15: 8 | V15: พี่มิ้ว(แอดมิน) | W15: 14000 | X15: 466.66667 | Z15: =$Z$6*BC16 -> 0 | BC15: =SUM(AA15:BB15) -> 0 | BD15: =(BC15*X15)+Y15+Z15 -> 0
B16: 7 | U16: 9 | V16: พี่ดี๋ | W16: 50000 | X16: 1666.6667 | Z16: =$Z$6*BC17 -> 1400 | BC16: =SUM(AA16:BB16) -> 0 | BD16: =(BC16*X16)+Y16+Z16 -> 1400
B17: 8 | U17: 10 | V17: พี่เจมส์ | W17: 17000 | X17: 566.66667 | Z17: =$Z$6*BC18 -> 0 | AG17: 1 | AH17: 1 | AI17: 1 | AJ17: 1 | AK17: 1 | AL17: 1 | AN17: 1 | AO17: 1 | AP17: 1 | AQ17: 1 | AR17: 1 | AS17: 1 | AU17: 1 | AV17: 1 | BC17: =SUM(AA17:BB17) -> 14 | BD17: =(BC17*X17)+Y17+Z17 -> 7933.3333
B18: 9 | U18: 11 | V18: อั้ม | W18: 20000 | X18: 666.66667 | Z18: =$Z$6*BC19 -> 1400 | BC18: =SUM(AA18:BB18) -> 0 | BD18: =(BC18*X18)+Y18+Z18 -> 1400
B19: 10 | U19: 12 | V19: พี่เต้ย (รายวัน) | W19: 4950 | X19: 450 | Z19: =$Z$6*BC20 -> 0 | AG19: 1 | AH19: 1 | AI19: 1 | AJ19: 1 | AK19: 1 | AL19: 1 | AN19: 1 | AO19: 1 | AP19: 1 | AQ19: 1 | AR19: 1 | AS19: 1 | AU19: 1 | AV19: 1 | BC19: =SUM(AA19:BB19) -> 14 | BD19: =(BC19*X19)+Y19+Z19 -> 6300
B20: 11 | U20: 13 | V20: จิว(ฝึกงาน) | W20: 3300 | X20: 300 | Z20: =$Z$6*BC21 -> 0 | BC20: =SUM(AA20:BB20) -> 0 | BD20: =(BC20*X20)+Y20+Z20 -> 0
B21: 12 | U21: 14 | V21: บอล(ฝึกงาน300) | W21: 3300 | X21: 300 | Z21: =$Z$6*BC22 -> 0 | BC21: =SUM(AA21:BB21) -> 0 | BD21: =(BC21*X21)+Y21+Z21 -> 0
B22: 13 | U22: 15 | V22: มุก(ฝึกงาน) | W22: 3300 | X22: 300 | Z22: =$Z$6*BC23 -> 0 | BC22: =SUM(AA22:BB22) -> 0 | BD22: =(BC22*X22)+Y22+Z22 -> 0
B23: 14 | U23: 16 | V23: เบนซ์(ฝึกงาน300) | W23: 3300 | X23: 300 | Z23: =$Z$6*BC24 -> 1900 | BC23: =SUM(AA23:BB23) -> 0 | BD23: =(BC23*X23)+Y23+Z23 -> 1900
B24: 15 | U24: 17 | V24: เต๋า(ฝึกงาน) | W24: 2700 | X24: 300 | Z24: =$Z$6*BC25 -> 1900 | AA24: 1 | AB24: 1 | AC24: 1 | AD24: 1 | AE24: 1 | AG24: 1 | AH24: 1 | AI24: 1 | AJ24: 1 | AK24: 1 | AL24: 1 | AN24: 1 | AO24: 1 | AP24: 1 | AQ24: 1 | AR24: 1 | AS24: 1 | AU24: 1 | AV24: 1 | BC24: =SUM(AA24:BB24) -> 19 | BD24: =(BC24*X24)+Y24+Z24 -> 7600
B25: 16 | U25: 18 | V25: เฟียส(ฝึกงาน) | W25: 2200 | X25: 200 | Z25: =$Z$6*BC26 -> 1900 | AA25: 1 | AB25: 1 | AC25: 1 | AD25: 1 | AE25: 1 | AG25: 1 | AH25: 1 | AI25: 1 | AJ25: 1 | AK25: 1 | AL25: 1 | AN25: 1 | AO25: 1 | AP25: 1 | AQ25: 1 | AR25: 1 | AS25: 1 | AU25: 1 | AV25: 1 | BC25: =SUM(AA25:BB25) -> 19 | BD25: =(BC25*X25)+Y25+Z25 -> 5700
B26: 17 | U26: 19 | V26: ฟลุ๊ค(ฝึกงาน) | W26: 1440 | X26: 180 | Z26: =$Z$6*BC27 -> 0 | AA26: 1 | AB26: 1 | AC26: 1 | AD26: 1 | AE26: 1 | AG26: 1 | AH26: 1 | AI26: 1 | AJ26: 1 | AK26: 1 | AL26: 1 | AN26: 1 | AO26: 1 | AP26: 1 | AQ26: 1 | AR26: 1 | AS26: 1 | AU26: 1 | AV26: 1 | BC26: =SUM(AA26:BB26) -> 19 | BD26: =(BC26*X26)+Y26+Z26 -> 3420
B27: 18 | U27: 20 | V27: เจมส์(ฝึกงาน) | W27: 2160 | X27: 180 | Z27: =$Z$6*BC28 -> 1400 | BC27: =SUM(AA27:BB27) -> 0 | BD27: =(BC27*X27)+Y27+Z27 -> 1400
B28: 19 | U28: 21 | V28: นาย(ฝึกงาน) | W28: 1980 | X28: 180 | Z28: =$Z$6*BC29 -> 0 | AG28: 1 | AH28: 1 | AI28: 1 | AJ28: 1 | AK28: 1 | AL28: 1 | AN28: 1 | AO28: 1 | AP28: 1 | AQ28: 1 | AR28: 1 | AS28: 1 | AU28: 1 | AV28: 1 | BC28: =SUM(AA28:BB28) -> 14 | BD28: =(BC28*X28)+Y28+Z28 -> 2520
B29: 20 | U29: 22 | V29: ดิว(ฝึกงาน) | W29: 1440 | X29: 180 | Z29: =$Z$6*BC30 -> 0 | BC29: =SUM(AA29:BB29) -> 0 | BD29: =(BC29*X29)+Y29+Z29 -> 0
B30: 21 | U30: 23 | V30: น็อต(ฝึกงาน) | W30: 2160 | X30: 180 | Z30: =$Z$6*BC31 -> 1400 | BC30: =SUM(AA30:BB30) -> 0 | BD30: =(BC30*X30)+Y30+Z30 -> 1400
B31: 22 | U31: 24 | V31: อาม(ฝึกงาน) | W31: 1980 | X31: 180 | Z31: =$Z$6*BC32 -> 0 | AG31: 1 | AH31: 1 | AI31: 1 | AJ31: 1 | AK31: 1 | AL31: 1 | AN31: 1 | AO31: 1 | AP31: 1 | AQ31: 1 | AR31: 1 | AS31: 1 | AU31: 1 | AV31: 1 | BC31: =SUM(AA31:BB31) -> 14 | BD31: =(BC31*X31)+Y31+Z31 -> 2520
B32: 23 | BD32: =SUM(BD8:BD31) -> 89976.667
B33: 24
B34: 25
B35: 26
B36: 27
B37: 28
B38: 29
B39: 30
B40: 31
...

Sheet PC-007 บ้านลาดกระบัง
B1: Factory/Company | C1: ='All Job balance report'!D13 -> Unity System Co., Ltd. | H1: Start Date | I1: 45809
B2: Project Name | C2: ='All Job balance report'!F13 -> งานค่าแรงผู้รับเหมา รพ.ภัทรเวช | H2: Sale Up Date
B3: Job Code. | C3: =C45 -> UNT-2601/001
B4: Quotation No. | E4: PROJECT BUDGET RECORD | H4: INVOICE (%) | I4: 0
B5: Contract Price | C5: =C46 -> 143840.18
B6: Budget Price | C6: =F57 -> 0
B7: PROFIT | C7: =(C5-C6)/C5 -> 1 | D7: ACTUAL | E7: 1
B8: No. | C8: Vendor Name | D8: Material Number | E8: Description | F8: Text/Quo.No. | G8: Amount | H8: Updated By | I8: Date | J8: PO
B10: 1 | C10: N.R.E | D10: 10 | E10: ราง Cable tray | F10: SUV-250107744 | G10: 9469.1 | H10: K.Kowit | I10: 45833 | J10: PO2025060023
B11: 2 | C11: บริษัท สยาม โคสทอล อินเตอร์เทรด จำกัด | D11: 10 | E11: MDB Panel | F11: 0267LC68SC | G11: 57500 | H11: K.Kowit | I11: 45832 | J11: PO2025060021
B12: 3 | C12: N.R.E | D12: 10 | E12: ท่ออ่อน PVC. | F12: SUV-250106117 | G12: 12900 | H12: K.Kowit | I12: 45798 | J12: PO2025050011
B13: 4 | C13: N.R.E | D13: 10 | E13: Fitting ราง Cable Tray | F13: SUV-250109340 | G13: 4188.8 | H13: K.Kowit | I13: 45833 | J13: PO2025080001
B14: 5 | C14: N.R.E | D14: 10 | E14: Load Center | F14: SUV-250107045 | G14: 46196.8 | H14: K.Kowit | I14: 45820 | J14: PO2025060012
B15: 6
F40: TOTAL COST | G40: =SUM(G9:G39) -> 130254.7
F41: BALANCE | G41: =$C$6-G40 -> -130254.7
F43: All BALANCE | G43: =G41/C6 -> #DIV/0!
B45: Job. Code. | C45: ='All Job balance report'!B13 -> UNT-2601/001
B46: Contract Price | C46: ='All Job balance report'!G13 -> 143840.18
B47: No. | C47: Code | E47: Description | F47: Budget | G47: Expense Record | H47: Balance | I47: Remark
B49: 1 | C49: 10 | E49: MATERIALS | F49: 0 | G49: =SUMIF($D$10:$D$39,$C$49,$G$10:$G$39) -> 130254.7 | H49: =F49-G49 -> -130254.7
B50: 2 | C50: 20 | E50: SUB CONTRACTOR | F50: 0 | G50: =SUMIF($D$10:$D$39,$C$50,$G$10:$G$39) -> 0 | H50: =F50-G50 -> 0
B51: 3 | C51: 30 | E51: HEAVY EQUIPMENT | F51: 0 | G51: =SUMIF($D$10:$D$39,$C$51,$G$10:$G$39) -> 0 | H51: =F51-G51 -> 0
B52: 4 | C52: 40 | E52: RENTAL | F52: 0 | G52: =SUMIF($D$10:$D$39,$C$52,$G$10:$G$39) -> 0 | H52: =F52-G52 -> 0
B53: 5 | C53: 50 | E53: STAFF EXPENSE | F53: 0 | G53: =SUMIF($D$10:$D$39,$C$53,$G$10:$G$39) -> 0 | H53: =F53-G53 -> 0
B54: 6 | C54: 60 | E54: OFFICE EXPENSE | F54: 0 | G54: =SUMIF($D$10:$D$39,$C$54,$G$10:$G$39) -> 0 | H54: =F54-G54 -> 0
B55: 7 | C55: 70 | E55: ENTERTAIN | F55: 0 | G55: =SUMIF($D$10:$D$39,$C$55,$G$10:$G$39) -> 0 | H55: =F55-G55 -> 0
B56: 8 | C56: 80 | E56: MISCELLANEOUS | F56: 0 | G56: =SUMIF($D$10:$D$39,$C$56,$G$10:$G$39) -> 0 | H56: =F56-G56 -> 0
E57: Total | F57: =SUM(F49:F56) -> 0 | G57: =SUM(G49:G56) -> 130254.7 | H57: =SUM(H49:H56) -> -130254.7
E58: % Profit | F58: =((C46-F57)/C46) -> 1
E59: Total Profit | F59: =F58*C46 -> 143840.18
E60: Gross Profit | F60: =C46-G57 -> 13585.48

Sheet XP-001 งานนครนายก
B1: Factory/Company | C1: ='All Job balance report'!D12 -> บริษัท เจตภัทร คอนสตรัคชั่น แอนด์ ดีไซน์ จำกัด | H1: Start Date | I1: 45818
B2: Project Name | C2: ='All Job balance report'!F12 -> งานติดตั้งคอนโด The Line Vibe ห้อง549 | H2: Sale Up Date
B3: Job Code. | C3: =C52 -> JEP-2601/001
B4: Quotation No. | E4: PROJECT BUDGET RECORD | H4: INVOICE (%) | I4: 0 | AA4: 45811 | AB4: 45812 | AC4: 45813 | AD4: 45814 | AE4: 45815 | AF4: 45816 | AG4: 45817 | AH4: 45818 | AI4: 45819 | AJ4: 45820 | AK4: 45821 | AL4: 45822 | AM4: 45823 | AN4: 45824 | AO4: 45825 | AP4: 45826 | AQ4: 45827 | AR4: 45828 | AS4: 45829 | AT4: 45830 | AU4: 45831 | AV4: 45832 | AW4: 45833 | AX4: 45834 | AY4: 45835 | AZ4: 45836 | BA4: 45837 | BB4: 45838 | BE4: 45839 | BF4: 45840 | BG4: 45841 | BH4: 45842 | BI4: 45843 | BJ4: 45844 | BK4: 45845 | BL4: 45846 | BM4: 45847 | BN4: 45848 | BO4: 45849 | BP4: 45850 | BQ4: 45851 | BR4: 45852 | BS4: 45853 | BT4: 45854 | BU4: 45855 | BV4: 45856 | BW4: 45857
B5: Contract Price | C5: =C53 -> 12000
B6: Budget Price | C6: =F64 -> 98300 | Z6: 100
B7: PROFIT | C7: =(C5-C6)/C5 -> -7.1916667 | D7: ACTUAL | E7: 1 | U7: No. | V7: Name | W7: Salary | X7: S per Day | Y7: ค่าโทรศัพท์ | Z7: ค่าอื่นๆ | AA7: =SUM(AA8:AA31) -> 4 | AB7: =SUM(AB8:AB31) -> 3 | AC7: =SUM(AC8:AC31) -> 3 | AD7: =SUM(AD8:AD31) -> 3 | AE7: =SUM(AE8:AE31) -> 3 | AF7: =SUM(AF8:AF31) -> 0 | AG7: =SUM(AG8:AG31) -> 11 | AH7: =SUM(AH8:AH31) -> 11 | ... BB7: =SUM(BB8:BB31) -> 0 | BE7: =SUM(BE8:BE31) -> 0 | BF7: =SUM(BF8:BF31) -> 0 | BG7: =SUM(BG8:BG31) -> 0 | BH7: =SUM(BH8:BH31) -> 0 | BI7: =SUM(BI8:BI31) -> 0 | BJ7: =SUM(BJ8:BJ31) -> 0 | BK7: =SUM(BK8:BK31) -> 0 | BL7: =SUM(BL8:BL31) -> 0 | ... BW7: =SUM(BW8:BW31) -> 0
B8: No. | C8: Vendor Name | D8: Material Number | E8: Description | F8: Text/Quo.No. | G8: Amount | H8: Updated By | I8: Date | J8: PO | U8: 1 | V8: พี่เอ็ก | W8: 31500 | X8: 1050 | Y8: 1400 | AG8: 1 | AH8: 1 | AI8: 1 | AJ8: 1 | AK8: 1 | AL8: 1 | AN8: 1 | AO8: 1 | AP8: 1 | AQ8: 1 | AR8: 1 | AS8: 1 | AU8: 1 | AV8: 1 | BC8: =SUM(AA8:BB8) -> 14 | BD8: =(BC8*X8)+Y8+Z8 -> 16100
U9: 2 | V9: เอลฟ์ | W9: 21300 | X9: 710 | Y9: 1400 | Z9: 2000 | AA9: 1 | AG9: 1 | AH9: 1 | AI9: 1 | AJ9: 1 | AK9: 1 | AL9: 1 | AN9: 1 | AO9: 1 | AP9: 1 | AQ9: 1 | AR9: 1 | AS9: 1 | AU9: 1 | AV9: 1 | BC9: =SUM(AA9:BB9) -> 15 | BD9: =(BC9*X9)+Y9+Z9 -> 14050
B10: 1 | C10: NRE | D10: 10 | E10: ราคาราง Cable Tray | G10: 35608.8 | H10: K.Kowit | I10: 45821 | J10: PO2025060014 | U10: 3 | V10: เฮียนิ้ง | W10: 18500 | X10: 616.66667 | Z10: =$Z$6*BC11 -> 1400 | BC10: =SUM(AA10:BB10) -> 0 | BD10: =(BC10*X10)+Y10+Z10 -> 1400
B11: 2 | C11: บริษัท สยาม โคสทอล อินเตอร์เทรด จำกัด | D11: 10 | E11: มิเตอร์ Digitakl Meter Schneider | G11: 5500 | H11: K.Kowit | I11: 45825 | J11: PO2025060018 | U11: 4 | V11: หนึ่ง | W11: 15000 | X11: 500 | Z11: =$Z$6*BC12 -> 1400 | AG11: 1 | AH11: 1 | AI11: 1 | AJ11: 1 | AK11: 1 | AL11: 1 | AN11: 1 | AO11: 1 | AP11: 1 | AQ11: 1 | AR11: 1 | AS11: 1 | AU11: 1 | AV11: 1 | BC11: =SUM(AA11:BB11) -> 14 | BD11: =(BC11*X11)+Y11+Z11 -> 8400
B12: 3 | C12: บริษัท สยาม โคสทอล อินเตอร์เทรด จำกัด | D12: 10 | E12: Steel Plate | G12: 10000 | H12: K.Kowit | I12: 45833 | J12: PO2025060022 | U12: 5 | V12: แอล | W12: 14000 | X12: 466.66667 | Z12: =$Z$6*BC13 -> 0 | AG12: 1 | AH12: 1 | AI12: 1 | AJ12: 1 | AK12: 1 | AL12: 1 | AN12: 1 | AO12: 1 | AP12: 1 | AQ12: 1 | AR12: 1 | AS12: 1 | AU12: 1 | AV12: 1 | BC12: =SUM(AA12:BB12) -> 14 | BD12: =(BC12*X12)+Y12+Z12 -> 6533.3333
B13: 4 | C13: ซื้อของทั่วไป | D13: 10 | G13: 3000 | H13: Sarawut | I13: 45833 | U13: 6 | V13: เวฟ | W13: 14000 | X13: 466.66667 | Z13: =$Z$6*BC14 -> 0 | BC13: =SUM(AA13:BB13) -> 0 | BD13: =(BC13*X13)+Y13+Z13 -> 0
B14: 5 | C14: ทีมงาน SEE พี่โจ๊ส | D14: 20 | G14: 32000 | H14: K.Kowit | I14: 45833 | U14: 78 | V14: บาส | W14: 13000 | X14: 433.33333 | Z14: =$Z$6*BC15 -> 0 | BC14: =SUM(AA14:BB14) -> 0 | BD14: =(BC14*X14)+Y14+Z14 -> 0
B15: 6 | D15: 10 | E15: ค่าน้ำมัน | G15: 500 | H15: K.Kowit | I15: 45847 | U15: 8 | V15: พี่มิ้ว(แอดมิน) | W15: 14000 | X15: 466.66667 | Z15: =$Z$6*BC16 -> 0 | BC15: =SUM(AA15:BB15) -> 0 | BD15: =(BC15*X15)+Y15+Z15 -> 0
B16: 7 | D16: 10 | E16: ค่าเหล็ก | G16: 1240 | H16: K.Kowit | I16: 45847 | U16: 9 | V16: พี่ดี๋ | W16: 50000 | X16: 1666.6667 | Z16: =$Z$6*BC17 -> 1400 | BC16: =SUM(AA16:BB16) -> 0 | BD16: =(BC16*X16)+Y16+Z16 -> 1400
B17: 8 | D17: 10 | E17: ค่าเหล็ก | G17: 240 | H17: K.Kowit | I17: 45847 | U17: 10 | V17: พี่เจมส์ | W17: 17000 | X17: 566.66667 | Z17: =$Z$6*BC18 -> 0 | AG17: 1 | AH17: 1 | AI17: 1 | AJ17: 1 | AK17: 1 | AL17: 1 | AN17: 1 | AO17: 1 | AP17: 1 | AQ17: 1 | AR17: 1 | AS17: 1 | AU17: 1 | AV17: 1 | BC17: =SUM(AA17:BB17) -> 14 | BD17: =(BC17*X17)+Y17+Z17 -> 7933.3333
B18: 9 | D18: 10 | E18: ซื้อแผ่นเหล็กเพิ่มอีก 2 แผ่น | G18: 2000 | H18: K.Kowit | I18: 45847 | U18: 11 | V18: อั้ม | W18: 20000 | X18: 666.66667 | Z18: =$Z$6*BC19 -> 1400 | BC18: =SUM(AA18:BB18) -> 0 | BD18: =(BC18*X18)+Y18+Z18 -> 1400
B19: 10 | D19: 50 | E19: ค่าแรงทีมงาน | G19: 5307 | H19: K.Kowit | I19: 45847 | N19: 668 | O19: =N19*P19 -> 2004 | P19: 3 | R19: =N19/8 -> 83.5 | S19: 10 | T19: =S19*R19 -> 835 | U19: 12 | V19: พี่เต้ย (รายวัน) | W19: 4950 | X19: 450 | Z19: =$Z$6*BC20 -> 0 | AG19: 1 | AH19: 1 | AI19: 1 | AJ19: 1 | AK19: 1 | AL19: 1 | AN19: 1 | AO19: 1 | AP19: 1 | AQ19: 1 | AR19: 1 | AS19: 1 | AU19: 1 | AV19: 1 | BC19: =SUM(AA19:BB19) -> 14 | BD19: =(BC19*X19)+Y19+Z19 -> 6300
B20: 11 | D20: 50 | E20: ค่าน้ำมันรถ | G20: 2000 | H20: K.Kowit | I20: 45847 | N20: 468 | O20: =N20*P20 -> 468 | P20: 1 | U20: 13 | V20: จิว(ฝึกงาน) | W20: 3300 | X20: 300 | Z20: =$Z$6*BC21 -> 0 | BC20: =SUM(AA20:BB20) -> 0 | BD20: =(BC20*X20)+Y20+Z20 -> 0
B21: 12 | C21: ฮาร์ดแวร์เฮาส์ | D21: 10 | E21: ค่าสี และแผ่นเหล็ก | G21: 976 | H21: K.Kowit | I21: 45847 | U21: 14 | V21: บอล(ฝึกงาน300) | W21: 3300 | X21: 300 | Z21: =$Z$6*BC22 -> 0 | BC21: =SUM(AA21:BB21) -> 0 | BD21: =(BC21*X21)+Y21+Z21 -> 0
B22: 13 | O22: =O20+O19+T19 -> 3307 | U22: 15 | V22: มุก(ฝึกงาน) | W22: 3300 | X22: 300 | Z22: =$Z$6*BC23 -> 0 | BC22: =SUM(AA22:BB22) -> 0 | BD22: =(BC22*X22)+Y22+Z22 -> 0
B23: 14 | N23: 2000 | U23: 16 | V23: เบนซ์(ฝึกงาน300) | W23: 3300 | X23: 300 | Z23: =$Z$6*BC24 -> 1900 | BC23: =SUM(AA23:BB23) -> 0 | BD23: =(BC23*X23)+Y23+Z23 -> 1900
B24: 15 | U24: 17 | V24: เต๋า(ฝึกงาน) | W24: 2700 | X24: 300 | Z24: =$Z$6*BC25 -> 1900 | AA24: 1 | AB24: 1 | AC24: 1 | AD24: 1 | AE24: 1 | AG24: 1 | AH24: 1 | AI24: 1 | AJ24: 1 | AK24: 1 | AL24: 1 | AN24: 1 | AO24: 1 | AP24: 1 | AQ24: 1 | AR24: 1 | AS24: 1 | AU24: 1 | AV24: 1 | BC24: =SUM(AA24:BB24) -> 19 | BD24: =(BC24*X24)+Y24+Z24 -> 7600
B25: 16 | U25: 18 | V25: เฟียส(ฝึกงาน) | W25: 2200 | X25: 200 | Z25: =$Z$6*BC26 -> 1900 | AA25: 1 | AB25: 1 | AC25: 1 | AD25: 1 | AE25: 1 | AG25: 1 | AH25: 1 | AI25: 1 | AJ25: 1 | AK25: 1 | AL25: 1 | AN25: 1 | AO25: 1 | AP25: 1 | AQ25: 1 | AR25: 1 | AS25: 1 | AU25: 1 | AV25: 1 | BC25: =SUM(AA25:BB25) -> 19 | BD25: =(BC25*X25)+Y25+Z25 -> 5700
B26: 17 | U26: 19 | V26: ฟลุ๊ค(ฝึกงาน) | W26: 1440 | X26: 180 | Z26: =$Z$6*BC27 -> 0 | AA26: 1 | AB26: 1 | AC26: 1 | AD26: 1 | AE26: 1 | AG26: 1 | AH26: 1 | AI26: 1 | AJ26: 1 | AK26: 1 | AL26: 1 | AN26: 1 | AO26: 1 | AP26: 1 | AQ26: 1 | AR26: 1 | AS26: 1 | AU26: 1 | AV26: 1 | BC26: =SUM(AA26:BB26) -> 19 | BD26: =(BC26*X26)+Y26+Z26 -> 3420
B27: 18 | U27: 20 | V27: เจมส์(ฝึกงาน) | W27: 2160 | X27: 180 | Z27: =$Z$6*BC28 -> 1400 | BC27: =SUM(AA27:BB27) -> 0 | BD27: =(BC27*X27)+Y27+Z27 -> 1400
B28: 19 | U28: 21 | V28: นาย(ฝึกงาน) | W28: 1980 | X28: 180 | Z28: =$Z$6*BC29 -> 0 | AG28: 1 | AH28: 1 | AI28: 1 | AJ28: 1 | AK28: 1 | AL28: 1 | AN28: 1 | AO28: 1 | AP28: 1 | AQ28: 1 | AR28: 1 | AS28: 1 | AU28: 1 | AV28: 1 | BC28: =SUM(AA28:BB28) -> 14 | BD28: =(BC28*X28)+Y28+Z28 -> 2520
B29: 20 | U29: 22 | V29: ดิว(ฝึกงาน) | W29: 1440 | X29: 180 | Z29: =$Z$6*BC30 -> 0 | BC29: =SUM(AA29:BB29) -> 0 | BD29: =(BC29*X29)+Y29+Z29 -> 0
B30: 21 | U30: 23 | V30: น็อต(ฝึกงาน) | W30: 2160 | X30: 180 | Z30: =$Z$6*BC31 -> 1400 | BC30: =SUM(AA30:BB30) -> 0 | BD30: =(BC30*X30)+Y30+Z30 -> 1400
B31: 22 | U31: 24 | V31: อาม(ฝึกงาน) | W31: 1980 | X31: 180 | Z31: =$Z$6*BC32 -> 0 | AG31: 1 | AH31: 1 | AI31: 1 | AJ31: 1 | AK31: 1 | AL31: 1 | AN31: 1 | AO31: 1 | AP31: 1 | AQ31: 1 | AR31: 1 | AS31: 1 | AU31: 1 | AV31: 1 | BC31: =SUM(AA31:BB31) -> 14 | BD31: =(BC31*X31)+Y31+Z31 -> 2520
B32: 23 | BD32: =SUM(BD8:BD31) -> 89976.667
B33: 24
B34: 25
B35: 26
B36: 27
B37: 28
B38: 29
B39: 30
B40: 31
...

Sheet MC-002 Udonthani
B1: Factory/Company | C1: Mc.Tric Public Company Limited | H1: Start Date | I1: 45833
B2: Project Name | C2: 22kV. Pole and Underground project | H2: Sale Up Date
B3: Job Code. | C3: =C52 -> PKE-2500/002
B4: Quotation No. | E4: PROJECT BUDGET RECORD | H4: INVOICE (%) | I4: 0 | AA4: 45811 | AB4: 45812 | AC4: 45813 | AD4: 45814 | AE4: 45815 | AF4: 45816 | AG4: 45817 | AH4: 45818 | AI4: 45819 | AJ4: 45820 | AK4: 45821 | AL4: 45822 | AM4: 45823 | AN4: 45824 | AO4: 45825 | AP4: 45826 | AQ4: 45827 | AR4: 45828 | AS4: 45829 | AT4: 45830 | AU4: 45831 | AV4: 45832 | AW4: 45833 | AX4: 45834 | AY4: 45835 | AZ4: 45836 | BA4: 45837 | BB4: 45838 | BE4: 45839 | BF4: 45840 | BG4: 45841 | BH4: 45842 | BI4: 45843 | BJ4: 45844 | BK4: 45845 | BL4: 45846 | BM4: 45847 | BN4: 45848 | BO4: 45849 | BP4: 45850 | BQ4: 45851 | BR4: 45852 | BS4: 45853 | BT4: 45854 | BU4: 45855 | BV4: 45856 | BW4: 45857
B5: Contract Price | C5: =C53 -> 7000
B6: Budget Price | C6: =F64 -> 5867101 | Z6: 100
B7: PROFIT | C7: =(C5-C6)/C5 -> -837.15729 | D7: ACTUAL | E7: 1 | U7: No. | V7: Name | W7: Salary | X7: S per Day | Y7: ค่าโทรศัพท์ | Z7: ค่าอื่นๆ | AA7: =SUM(AA8:AA31) -> 4 | AB7: =SUM(AB8:AB31) -> 3 | AC7: =SUM(AC8:AC31) -> 3 | AD7: =SUM(AD8:AD31) -> 3 | AE7: =SUM(AE8:AE31) -> 3 | AF7: =SUM(AF8:AF31) -> 0 | AG7: =SUM(AG8:AG31) -> 11 | AH7: =SUM(AH8:AH31) -> 11 | ... BB7: =SUM(BB8:BB31) -> 0 | BE7: =SUM(BE8:BE31) -> 0 | BF7: =SUM(BF8:BF31) -> 0 | BG7: =SUM(BG8:BG31) -> 0 | BH7: =SUM(BH8:BH31) -> 0 | BI7: =SUM(BI8:BI31) -> 0 | BJ7: =SUM(BJ8:BJ31) -> 0 | BK7: =SUM(BK8:BK31) -> 0 | BL7: =SUM(BL8:BL31) -> 0 | ... BW7: =SUM(BW8:BW31) -> 0
B8: No. | C8: Vendor Name | D8: Material Number | E8: Description | F8: Text/Quo.No. | G8: Amount | H8: Updated By | I8: Date | J8: PO | U8: 1 | V8: พี่เอ็ก | W8: 31500 | X8: 1050 | Y8: 1400 | AG8: 1 | AH8: 1 | AI8: 1 | AJ8: 1 | AK8: 1 | AL8: 1 | AN8: 1 | AO8: 1 | AP8: 1 | AQ8: 1 | AR8: 1 | AS8: 1 | AU8: 1 | AV8: 1 | BC8: =SUM(AA8:BB8) -> 14 | BD8: =(BC8*X8)+Y8+Z8 -> 16100
U9: 2 | V9: เอลฟ์ | W9: 21300 | X9: 710 | Y9: 1400 | Z9: 2000 | AA9: 1 | AG9: 1 | AH9: 1 | AI9: 1 | AJ9: 1 | AK9: 1 | AL9: 1 | AN9: 1 | AO9: 1 | AP9: 1 | AQ9: 1 | AR9: 1 | AS9: 1 | AU9: 1 | AV9: 1 | BC9: =SUM(AA9:BB9) -> 15 | BD9: =(BC9*X9)+Y9+Z9 -> 14050
B10: 1 | C10: ตั๋วเครื่องบิน | D10: 80 | E10: บินไปสำรวจหน้างานก่อนเสนอราคา | G10: 8000 | H10: K.Kowit | I10: 45802 | U10: 3 | V10: เฮียนิ้ง | W10: 18500 | X10: 616.66667 | Z10: =$Z$6*BC11 -> 1400 | BC10: =SUM(AA10:BB10) -> 0 | BD10: =(BC10*X10)+Y10+Z10 -> 1400
B11: 2 | C11: ตั๋วเครื่องบิน | D11: 80 | E11: บินไปประชุมกับลูกค้า Kick Off Meeting | G11: 3254 | H11: K.Kowit | I11: 45802 | U11: 4 | V11: หนึ่ง | W11: 15000 | X11: 500 | Z11: =$Z$6*BC12 -> 1400 | AG11: 1 | AH11: 1 | AI11: 1 | AJ11: 1 | AK11: 1 | AL11: 1 | AN11: 1 | AO11: 1 | AP11: 1 | AQ11: 1 | AR11: 1 | AS11: 1 | AU11: 1 | AV11: 1 | BC11: =SUM(AA11:BB11) -> 14 | BD11: =(BC11*X11)+Y11+Z11 -> 8400
B12: 3 | C12: ร้านเช่ารถ | D12: 80 | E12: ค่าเช่ารถ | G12: 4300 | H12: K.Kowit | I12: 45824 | U12: 5 | V12: แอล | W12: 14000 | X12: 466.66667 | Z12: =$Z$6*BC13 -> 0 | AG12: 1 | AH12: 1 | AI12: 1 | AJ12: 1 | AK12: 1 | AL12: 1 | AN12: 1 | AO12: 1 | AP12: 1 | AQ12: 1 | AR12: 1 | AS12: 1 | AU12: 1 | AV12: 1 | BC12: =SUM(AA12:BB12) -> 14 | BD12: =(BC12*X12)+Y12+Z12 -> 6533.3333
B13: 4 | C13: ร้านเช่ารถ | D13: 80 | E13: ค่าซ่อมรถเช่า | G13: 3000 | H13: K.Kowit | I13: 45824 | U13: 6 | V13: เวฟ | W13: 14000 | X13: 466.66667 | Z13: =$Z$6*BC14 -> 0 | BC13: =SUM(AA13:BB13) -> 0 | BD13: =(BC13*X13)+Y13+Z13 -> 0
B14: 5 | C14: โรงแรมบีทู | D14: 80 | E14: ค่าโรงแรม | G14: 855 | H14: K.Kowit | I14: 45826 | U14: 78 | V14: บาส | W14: 13000 | X14: 433.33333 | Z14: =$Z$6*BC15 -> 0 | BC14: =SUM(AA14:BB14) -> 0 | BD14: =(BC14*X14)+Y14+Z14 -> 0
B15: 6 | C15: โรงแรม UD | D15: 80 | E15: ค่าโรงแรม | G15: 850 | H15: K.Kowit | I15: 45826 | U15: 8 | V15: พี่มิ้ว(แอดมิน) | W15: 14000 | X15: 466.66667 | Z15: =$Z$6*BC16 -> 0 | BC15: =SUM(AA15:BB15) -> 0 | BD15: =(BC15*X15)+Y15+Z15 -> 0
B16: 7 | C16: บริษัท เค.ที.เอ็น เอ็นจิเนียริ่ง 1112 จำกัด (สำนักงานใหญ่) | D16: 20 | E16: งาน UG และลากสาย XLPE | G16: 2644700 | H16: K.Kowit | I16: 45824 | J16: PO2025060015 | U16: 9 | V16: พี่ดี๋ | W16: 50000 | X16: 1666.6667 | Z16: =$Z$6*BC17 -> 1400 | BC16: =SUM(AA16:BB16) -> 0 | BD16: =(BC16*X16)+Y16+Z16 -> 1400
B17: 8 | C17: บริษัท ทักษิณคอนกรีต จำกัด | D17: 10 | E17: ค่าเสาไฟ และคอร์น คอนกรีต | G17: 562400 | H17: K.Kowit | I17: 45841 | J17: PO2025070004 | U17: 10 | V17: พี่เจมส์ | W17: 17000 | X17: 566.66667 | Z17: =$Z$6*BC18 -> 0 | AG17: 1 | AH17: 1 | AI17: 1 | AJ17: 1 | AK17: 1 | AL17: 1 | AN17: 1 | AO17: 1 | AP17: 1 | AQ17: 1 | AR17: 1 | AS17: 1 | AU17: 1 | AV17: 1 | BC17: =SUM(AA17:BB17) -> 14 | BD17: =(BC17*X17)+Y17+Z17 -> 7933.3333
B18: 9 | D18: 80 | E18: เลี้ยงลูกค้า | G18: =1480+16280 -> 17760 | H18: K.Kowit | I18: 45867 | U18: 11 | V18: อั้ม | W18: 20000 | X18: 666.66667 | Z18: =$Z$6*BC19 -> 1400 | BC18: =SUM(AA18:BB18) -> 0 | BD18: =(BC18*X18)+Y18+Z18 -> 1400
B19: 10 | D19: 80 | E19: ทางด่วน เดินทางไปกลับอุดรธานี | G19: 145 | H19: K.Kowit | I19: 45867 | U19: 12 | V19: พี่เต้ย (รายวัน) | W19: 4950 | X19: 450 | Z19: =$Z$6*BC20 -> 0 | AG19: 1 | AH19: 1 | AI19: 1 | AJ19: 1 | AK19: 1 | AL19: 1 | AN19: 1 | AO19: 1 | AP19: 1 | AQ19: 1 | AR19: 1 | AS19: 1 | AU19: 1 | AV19: 1 | BC19: =SUM(AA19:BB19) -> 14 | BD19: =(BC19*X19)+Y19+Z19 -> 6300
B20: 11 | C20: ค่าน้ำมัน | D20: 80 | E20: ค่าน้ำมัน เดินทางไปกลับอุดรธานี | G20: 405 | H20: K.Kowit | I20: 45867 | U20: 13 | V20: จิว(ฝึกงาน) | W20: 3300 | X20: 300 | Z20: =$Z$6*BC21 -> 0 | BC20: =SUM(AA20:BB20) -> 0 | BD20: =(BC20*X20)+Y20+Z20 -> 0
B21: 12 | C21: ค่าน้ำมัน | D21: 80 | E21: ค่าน้ำมัน เดินทางไปกลับอุดรธานี | G21: 377 | H21: K.Kowit | I21: 45867 | U21: 14 | V21: บอล(ฝึกงาน300) | W21: 3300 | X21: 300 | Z21: =$Z$6*BC22 -> 0 | BC21: =SUM(AA21:BB21) -> 0 | BD21: =(BC21*X21)+Y21+Z21 -> 0
B22: 13 | C22: ค่าน้ำมัน | D22: 80 | E22: ค่าน้ำมัน เดินทางไปกลับอุดรธานี | G22: 380 | H22: K.Kowit | I22: 45867 | U22: 15 | V22: มุก(ฝึกงาน) | W22: 3300 | X22: 300 | Z22: =$Z$6*BC23 -> 0 | BC22: =SUM(AA22:BB22) -> 0 | BD22: =(BC22*X22)+Y22+Z22 -> 0
B23: 14 | C23: ค่าน้ำมัน | D23: 80 | E23: ค่าน้ำมัน เดินทางไปกลับอุดรธานี | G23: 400 | H23: K.Kowit | I23: 45867 | U23: 16 | V23: เบนซ์(ฝึกงาน300) | W23: 3300 | X23: 300 | Z23: =$Z$6*BC24 -> 1900 | BC23: =SUM(AA23:BB23) -> 0 | BD23: =(BC23*X23)+Y23+Z23 -> 1900
B24: 15 | C24: โรงแรม B2 | D24: 50 | E24: ค่าห้องพัก 1 | G24: 540 | H24: K.Kowit | I24: 45867 | U24: 17 | V24: เต๋า(ฝึกงาน) | W24: 2700 | X24: 300 | Z24: =$Z$6*BC25 -> 1900 | AA24: 1 | AB24: 1 | AC24: 1 | AD24: 1 | AE24: 1 | AG24: 1 | AH24: 1 | AI24: 1 | AJ24: 1 | AK24: 1 | AL24: 1 | AN24: 1 | AO24: 1 | AP24: 1 | AQ24: 1 | AR24: 1 | AS24: 1 | AU24: 1 | AV24: 1 | BC24: =SUM(AA24:BB24) -> 19 | BD24: =(BC24*X24)+Y24+Z24 -> 7600
B25: 16 | C25: โรงแรม B2 | D25: 50 | E25: ค่าห้องพัก 2 | G25: 620 | H25: K.Kowit | I25: 45867 | U25: 18 | V25: เฟียส(ฝึกงาน) | W25: 2200 | X25: 200 | Z25: =$Z$6*BC26 -> 1900 | AA25: 1 | AB25: 1 | AC25: 1 | AD25: 1 | AE25: 1 | AG25: 1 | AH25: 1 | AI25: 1 | AJ25: 1 | AK25: 1 | AL25: 1 | AN25: 1 | AO25: 1 | AP25: 1 | AQ25: 1 | AR25: 1 | AS25: 1 | AU25: 1 | AV25: 1 | BC25: =SUM(AA25:BB25) -> 19 | BD25: =(BC25*X25)+Y25+Z25 -> 5700
B26: 17 | C26: ซื้อของใช้ในไซด์ | D26: 10 | E26: ค่ารองเท้าและของใช้ในไซด์ | G26: 3559.06 | H26: K.Kowit | I26: 45867 | U26: 19 | V26: ฟลุ๊ค(ฝึกงาน) | W26: 1440 | X26: 180 | Z26: =$Z$6*BC27 -> 0 | AA26: 1 | AB26: 1 | AC26: 1 | AD26: 1 | AE26: 1 | AG26: 1 | AH26: 1 | AI26: 1 | AJ26: 1 | AK26: 1 | AL26: 1 | AN26: 1 | AO26: 1 | AP26: 1 | AQ26: 1 | AR26: 1 | AS26: 1 | AU26: 1 | AV26: 1 | BC26: =SUM(AA26:BB26) -> 19 | BD26: =(BC26*X26)+Y26+Z26 -> 3420
B27: 18 | U27: 20 | V27: เจมส์(ฝึกงาน) | W27: 2160 | X27: 180 | Z27: =$Z$6*BC28 -> 1400 | BC27: =SUM(AA27:BB27) -> 0 | BD27: =(BC27*X27)+Y27+Z27 -> 1400
B28: 19 | U28: 21 | V28: นาย(ฝึกงาน) | W28: 1980 | X28: 180 | Z28: =$Z$6*BC29 -> 0 | AG28: 1 | AH28: 1 | AI28: 1 | AJ28: 1 | AK28: 1 | AL28: 1 | AN28: 1 | AO28: 1 | AP28: 1 | AQ28: 1 | AR28: 1 | AS28: 1 | AU28: 1 | AV28: 1 | BC28: =SUM(AA28:BB28) -> 14 | BD28: =(BC28*X28)+Y28+Z28 -> 2520
B29: 20 | U29: 22 | V29: ดิว(ฝึกงาน) | W29: 1440 | X29: 180 | Z29: =$Z$6*BC30 -> 0 | BC29: =SUM(AA29:BB29) -> 0 | BD29: =(BC29*X29)+Y29+Z29 -> 0
B30: 21 | U30: 23 | V30: น็อต(ฝึกงาน) | W30: 2160 | X30: 180 | Z30: =$Z$6*BC31 -> 1400 | BC30: =SUM(AA30:BB30) -> 0 | BD30: =(BC30*X30)+Y30+Z30 -> 1400
B31: 22 | U31: 24 | V31: อาม(ฝึกงาน) | W31: 1980 | X31: 180 | Z31: =$Z$6*BC32 -> 0 | AG31: 1 | AH31: 1 | AI31: 1 | AJ31: 1 | AK31: 1 | AL31: 1 | AN31: 1 | AO31: 1 | AP31: 1 | AQ31: 1 | AR31: 1 | AS31: 1 | AU31: 1 | AV31: 1 | BC31: =SUM(AA31:BB31) -> 14 | BD31: =(BC31*X31)+Y31+Z31 -> 2520
B32: 23 | W32: =SUM(W8:W31) -> 262510 | BD32: =SUM(BD8:BD31) -> 89976.667
B33: 24
B34: 25
B35: 26
B36: 27
B37: 28
B38: 29
B39: 30
B40: 31
...

Sheet PPC-001 Nestle
B1: Factory/Company | C1: Prime Power Construction | H1: Start Date | I1: 45778
B2: Project Name | C2: 22kV. Pole installation | H2: Sale Up Date
B3: Job Code. | C3: =C63 -> SUT-2500/001
B4: Quotation No. | E4: PROJECT BUDGET RECORD | H4: INVOICE (%) | I4: 0 | AA4: 45811 | AB4: 45812 | AC4: 45813 | AD4: 45814 | AE4: 45815 | AF4: 45816 | AG4: 45817 | AH4: 45818 | AI4: 45819 | AJ4: 45820 | AK4: 45821 | AL4: 45822 | AM4: 45823 | AN4: 45824 | AO4: 45825 | AP4: 45826 | AQ4: 45827 | AR4: 45828 | AS4: 45829 | AT4: 45830 | AU4: 45831 | AV4: 45832 | AW4: 45833 | BA4: 45834 | BB4: 45835 | BC4: 45836 | BD4: 45837 | BE4: 45838 | BF4: 45839 | BG4: 45840 | BH4: 45841 | BI4: 45842 | BJ4: 45843 | BK4: 45844 | BL4: 45845 | BM4: 45846 | BN4: 45847 | BO4: 45848 | BP4: 45849 | BQ4: 45850 | BR4: 45851 | BS4: 45852 | BT4: 45853
B5: Contract Price | C5: =C64 -> 37500
B6: Budget Price | C6: =F75 -> 1397000 | Z6: 100 | AZ6: 100
B7: PROFIT | C7: =(C5-C6)/C5 -> -36.253333 | D7: ACTUAL | E7: 1 | U7: No. | V7: Name | W7: Salary | X7: S per Day | Y7: ค่าโทรศัพท์ | Z7: ค่าอื่นๆ | AA7: =SUM(AA8:AA31) -> 4 | AB7: =SUM(AB8:AB31) -> 3 | AC7: =SUM(AC8:AC31) -> 3 | AD7: =SUM(AD8:AD31) -> 3 | AE7: =SUM(AE8:AE31) -> 3 | AF7: =SUM(AF8:AF31) -> 0 | AG7: =SUM(AG8:AG31) -> 10 | AH7: =SUM(AH8:AH31) -> 10 | ... AW7: =SUM(AW8:AW31) -> 8 | BA7: =SUM(BA8:BA31) -> 8 | BB7: =SUM(BB8:BB31) -> 8 | BC7: =SUM(BC8:BC31) -> 8 | BD7: =SUM(BD8:BD31) -> 0 | BE7: =SUM(BE8:BE31) -> 7 | BF7: =SUM(BF8:BF31) -> 7 | BG7: =SUM(BG8:BG31) -> 6 | BH7: =SUM(BH8:BH31) -> 7 | ... BT7: =SUM(BT8:BT31) -> 7
B8: No. | C8: Vendor Name | D8: Material Number | E8: Description | F8: Text/Quo.No. | G8: Amount | H8: Updated By | I8: Date | J8: PO | U8: 1 | V8: พี่เอ็ก | W8: 31500 | X8: 1050 | Y8: 1400 | AG8: 1 | AH8: 1 | AI8: 1 | AJ8: 1 | AK8: 1 | AL8: 1 | AN8: 1 | AO8: 1 | AP8: 1 | AQ8: 1 | AR8: 1 | AS8: 1 | AU8: 1 | AV8: 1 | AW8: 1 | AX8: =SUM(AA8:AW8) -> 15 | AY8: =W8+$Y8+$Z8 -> 32900 | AZ8: =$AZ$6*BU8 -> 1600 | BA8: 1 | BB8: 1 | BC8: 1 | BE8: 1 | BF8: 1 | BG8: 1 | BH8: 1 | BI8: 1 | BJ8: 1 | BL8: 1 | BM8: 1 | BN8: 1 | BP8: 1 | BQ8: 1 | BS8: 1 | BT8: 1 | BU8: =SUM(BA8:BT8) -> 16 | BV8: =(BU8*$X8)+$Y8+$AZ8 -> 19800
U9: 2 | V9: เอลฟ์ | W9: 21300 | X9: 710 | Y9: 1400 | Z9: 2000 | AA9: 1 | AG9: 1 | AH9: 1 | AI9: 1 | AJ9: 1 | AK9: 1 | AL9: 1 | AN9: 1 | AO9: 1 | AP9: 1 | AQ9: 1 | AR9: 1 | AX9: =SUM(AA9:AW9) -> 12 | AY9: =(AX9*$X9)+$Y9+$Z9 -> 11920 | AZ9: =$AZ$6*BU9 -> 0 | BU9: =SUM(BA9:BT9) -> 0 | BV9: =(BU9*$X9)+$Y9+$AZ9 -> 1400
B10: 1 | C10: Siriprapa | D10: 10 | E10: PQM meter / EDMI Panel | F10: 68/05-05A-R1 | G10: 222000 | H10: K.Kowit | U10: 3 | V10: เฮียนิ้ง | W10: 18500 | X10: 616.66667 | Z10: =$Z$6*AX11 -> 1500 | AX10: =SUM(AA10:AW10) -> 0 | AZ10: =$AZ$6*BU10 -> 0 | BU10: =SUM(BA10:BT10) -> 0 | BV10: =(BU10*$X10)+$Y10+$AZ10 -> 0
B11: 2 | C11: Precise | D11: 10 | E11: อุปกรณ์ HV | F11: PO2025050018 | G11: 316060 | H11: K.Kowit | U11: 4 | V11: หนึ่ง | W11: 15000 | X11: 500 | Z11: =$Z$6*AX12 -> 1500 | AG11: 1 | AH11: 1 | AI11: 1 | AJ11: 1 | AK11: 1 | AL11: 1 | AN11: 1 | AO11: 1 | AP11: 1 | AQ11: 1 | AR11: 1 | AS11: 1 | AU11: 1 | AV11: 1 | AW11: 1 | AX11: =SUM(AA11:AW11) -> 15 | AY11: =W11+$Y11+$Z11 -> 16500 | AZ11: =$AZ$6*BU11 -> 1600 | BA11: 1 | BB11: 1 | BC11: 1 | BE11: 1 | BF11: 1 | BG11: 1 | BH11: 1 | BI11: 1 | BJ11: 1 | BL11: 1 | BM11: 1 | BN11: 1 | BP11: 1 | BQ11: 1 | BS11: 1 | BT11: 1 | BU11: =SUM(BA11:BT11) -> 16 | BV11: =(BU11*$X11)+$Y11+$AZ11 -> 9600
B12: 3 | C12: บริษัท ธราดล 2555 จำกัด | D12: 20 | E12: จ้างตัดคอนกรีต | F12: PO2025060004 | G12: 8800 | H12: K.Kowit | U12: 5 | V12: แอล | W12: 14000 | X12: 466.66667 | Z12: =$Z$6*AX13 -> 0 | AG12: 1 | AH12: 1 | AI12: 1 | AJ12: 1 | AK12: 1 | AL12: 1 | AN12: 1 | AO12: 1 | AP12: 1 | AQ12: 1 | AR12: 1 | AS12: 1 | AU12: 1 | AV12: 1 | AW12: 1 | AX12: =SUM(AA12:AW12) -> 15 | AY12: =(AX12*$X12)+$Y12+$Z12 -> 7000 | AZ12: =$AZ$6*BU12 -> 1600 | BA12: 1 | BB12: 1 | BC12: 1 | BE12: 1 | BF12: 1 | BG12: 1 | BH12: 1 | BI12: 1 | BJ12: 1 | BL12: 1 | BM12: 1 | BN12: 1 | BP12: 1 | BQ12: 1 | BS12: 1 | BT12: 1 | BU12: =SUM(BA12:BT12) -> 16 | BV12: =(BU12*$X12)+$Y12+$AZ12 -> 9066.6667
B13: 4 | C13: หจก. บีเอ็ม แอนด์ เบนซ์ ค้าวัสดุ (อยุธยา) | D13: 10 | F13: 999INV-2506-0160 | G13: 1046.73 | H13: K.Kowit | U13: 6 | V13: เวฟ | W13: 14000 | X13: 466.66667 | Z13: =$Z$6*AX14 -> 0 | AX13: =SUM(AA13:AW13) -> 0 | AZ13: =$AZ$6*BU13 -> 0 | BU13: =SUM(BA13:BT13) -> 0 | BV13: =(BU13*$X13)+$Y13+$AZ13 -> 0
B14: 5 | C14: เช่าเครื่องตัดปูน | D14: 40 | F14: QR-00184228 | G14: 1121.5 | H14: K.Kowit | U14: 78 | V14: บาส | W14: 13000 | X14: 433.33333 | Z14: =$Z$6*AX15 -> 0 | AX14: =SUM(AA14:AW14) -> 0 | AZ14: =$AZ$6*BU14 -> 0 | BU14: =SUM(BA14:BT14) -> 0 | BV14: =(BU14*$X14)+$Y14+$AZ14 -> 0
B15: 6 | C15: ส.อรุน | D15: 10 | E15: เสาคอนกรีต | F15: QT-25001984 | G15: 235239.5 | H15: K.Kowit | U15: 8 | V15: พี่มิ้ว(แอดมิน) | W15: 14000 | X15: 466.66667 | Z15: =$Z$6*AX16 -> 0 | AX15: =SUM(AA15:AW15) -> 0 | AZ15: =$AZ$6*BU15 -> 0 | BU15: =SUM(BA15:BT15) -> 0 | BV15: =(BU15*$X15)+$Y15+$AZ15 -> 0
B16: 7 | C16: ซ่อมรถ | D16: 30 | E16: ซ่อมรถสว่าน | F16: BL2025060012 | G16: 17500 | H16: K.Kowit | U16: 9 | V16: พี่ดี๋ | W16: 50000 | X16: 1666.6667 | Z16: =$Z$6*AX17 -> 0 | AX16: =SUM(AA16:AW16) -> 0 | AZ16: =$AZ$6*BU16 -> 0 | BU16: =SUM(BA16:BT16) -> 0 | BV16: =(BU16*$X16)+$Y16+$AZ16 -> 0
B17: 8 | C17: ร้านนครสวรรค์ | D17: 10 | E17: หัวเพชร เจาะดิน | G17: 3500 | H17: K.Kowit | U17: 10 | V17: พี่เจมส์ | W17: 17000 | X17: 566.66667 | Z17: =$Z$6*AX18 -> 0 | AX17: =SUM(AA17:AW17) -> 0 | AY17: =(AX17*$X17)+$Y17+$Z17 -> 0 | AZ17: =$AZ$6*BU17 -> 0 | BU17: =SUM(BA17:BT17) -> 0 | BV17: =(BU17*$X17)+$Y17+$AZ17 -> 0
B18: 9 | C18: ร้านค้าอุปกรณ์ก่อสร้าง | D18: 10 | E18: ชะแลง ไม้กวาด กรรไกรตัดเหล็ก | G18: 1093.46 | H18: K.Kowit | U18: 11 | V18: อั้ม | W18: 20000 | X18: 666.66667 | Z18: =$Z$6*AX19 -> 1500 | AX18: =SUM(AA18:AW18) -> 0 | AZ18: =$AZ$6*BU18 -> 0 | BU18: =SUM(BA18:BT18) -> 0 | BV18: =(BU18*$X18)+$Y18+$AZ18 -> 0
B19: 10 | C19: ร้านค้าอุปกรณ์ก่อสร้าง | D19: 10 | E19: กระสอบปุ๋ย | G19: 168.22 | H19: K.Kowit | U19: 12 | V19: พี่เต้ย (รายวัน) | W19: 4950 | X19: 450 | Z19: =$Z$6*AX20 -> 0 | AG19: 1 | AH19: 1 | AI19: 1 | AJ19: 1 | AK19: 1 | AL19: 1 | AN19: 1 | AO19: 1 | AP19: 1 | AQ19: 1 | AR19: 1 | AS19: 1 | AU19: 1 | AV19: 1 | AW19: 1 | AX19: =SUM(AA19:AW19) -> 15 | AY19: =(AX19*$X19)+$Y19+$Z19 -> 6750 | AZ19: =$AZ$6*BU19 -> 1500 | BA19: 1 | BB19: 1 | BC19: 1 | BE19: 1 | BF19: 1 | BH19: 1 | BI19: 1 | BJ19: 1 | BL19: 1 | BM19: 1 | BN19: 1 | BP19: 1 | BQ19: 1 | BS19: 1 | BT19: 1 | BU19: =SUM(BA19:BT19) -> 15 | BV19: =(BU19*$X19)+$Y19+$AZ19 -> 8250
B20: 11 | C20: SSI | D20: 10 | E20: ชุด KIT ต่อสาย 3M | G20: 2200 | H20: K.Kowit | U20: 13 | V20: จิว(ฝึกงาน) | W20: 3300 | X20: 300 | Z20: =$Z$6*AX21 -> 0 | AX20: =SUM(AA20:AW20) -> 0 | AZ20: =$AZ$6*BU20 -> 0 | BU20: =SUM(BA20:BT20) -> 0 | BV20: =(BU20*$X20)+$Y20+$AZ20 -> 0
B21: 12 | C21: ฮาร์ดแวร์เฮาส์ | D21: 10 | E21: เครื่องมือต่อสายไฟ | G21: 1102.1 | H21: K.Kowit | U21: 14 | V21: บอล(ฝึกงาน300) | W21: 3300 | X21: 300 | Z21: =$Z$6*AX22 -> 0 | AX21: =SUM(AA21:AW21) -> 0 | AZ21: =$AZ$6*BU21 -> 0 | BU21: =SUM(BA21:BT21) -> 0 | BV21: =(BU21*$X21)+$Y21+$AZ21 -> 0
B22: 13 | C22: ณัฐภูมิ อีควิปเม้นท์ จำกัด | D22: 10 | E22: ลูกถ้วยหัวเสา และเหล็ก คอร์น | G22: 210608.1 | H22: K.Kowit | U22: 15 | V22: มุก(ฝึกงาน) | W22: 3300 | X22: 300 | Z22: =$Z$6*AX23 -> 0 | AX22: =SUM(AA22:AW22) -> 0 | AZ22: =$AZ$6*BU22 -> 0 | BU22: =SUM(BA22:BT22) -> 0 | BV22: =(BU22*$X22)+$Y22+$AZ22 -> 0
B23: 14 | C23: กิจพูนชัย จำกัด | D23: 10 | E23: น๊อตประกอบหัวเสา | G23: 42061 | H23: K.Kowit | U23: 16 | V23: เบนซ์(ฝึกงาน300) | W23: 3300 | X23: 300 | Z23: =$Z$6*AX24 -> 1700 | AX23: =SUM(AA23:AW23) -> 0 | AZ23: =$AZ$6*BU23 -> 0 | BU23: =SUM(BA23:BT23) -> 0 | BV23: =(BU23*$X23)+$Y23+$AZ23 -> 0
B24: 15 | D24: 30 | E24: ค่าซ่อมรถลุงชาย | G24: 8000 | H24: K.Kowit | U24: 17 | V24: เต๋า(ฝึกงาน) | W24: 2700 | X24: 300 | Z24: =$Z$6*AX25 -> 2000 | AA24: 1 | AB24: 1 | AC24: 1 | AD24: 1 | AE24: 1 | AG24: 1 | AH24: 1 | AI24: 1 | AJ24: 1 | AK24: 1 | AL24: 1 | AN24: 1 | AO24: 1 | AP24: 1 | AQ24: 1 | AR24: 1 | AS24: 1 | AX24: =SUM(AA24:AW24) -> 17 | AY24: =(AX24*$X24)+$Y24+$Z24 -> 7100 | AZ24: =$AZ$6*BU24 -> 0 | BU24: =SUM(BA24:BT24) -> 0 | BV24: =(BU24*$X24)+$Y24+$AZ24 -> 0
B25: 16 | C25: ค่าแรง | D25: 50 | E25: ค่าแรงคนทำงานทั้งหมด | G25: =AY34 -> 159886.67 | H25: K.Kowit | U25: 18 | V25: เฟียส(ฝึกงาน) | W25: 2200 | X25: 200 | Z25: =$Z$6*AX26 -> 2000 | AA25: 1 | AB25: 1 | AC25: 1 | AD25: 1 | AE25: 1 | AG25: 1 | AH25: 1 | AI25: 1 | AJ25: 1 | AK25: 1 | AL25: 1 | AN25: 1 | AO25: 1 | AP25: 1 | AQ25: 1 | AR25: 1 | AS25: 1 | AU25: 1 | AV25: 1 | AW25: 1 | AX25: =SUM(AA25:AW25) -> 20 | AY25: =(AX25*$X25)+$Y25+$Z25 -> 6000 | AZ25: =$AZ$6*BU25 -> 1600 | BA25: 1 | BB25: 1 | BC25: 1 | BE25: 1 | BF25: 1 | BG25: 1 | BH25: 1 | BI25: 1 | BJ25: 1 | BL25: 1 | BM25: 1 | BN25: 1 | BP25: 1 | BQ25: 1 | BS25: 1 | BT25: 1 | BU25: =SUM(BA25:BT25) -> 16 | BV25: =(BU25*$X25)+$Y25+$AZ25 -> 4800
B26: 17 | C26: บ้านดินทอง | D26: 50 | E26: ค่าที่พัก 1 เดือน | G26: 13500 | H26: K.Kowit | I26: เริ่มพักวันที่ 9/6/2025 | U26: 19 | V26: ฟลุ๊ค(ฝึกงาน) | W26: 1440 | X26: 180 | Z26: =$Z$6*AX27 -> 0 | AA26: 1 | AB26: 1 | AC26: 1 | AD26: 1 | AE26: 1 | AG26: 1 | AH26: 1 | AI26: 1 | AJ26: 1 | AK26: 1 | AL26: 1 | AN26: 1 | AO26: 1 | AP26: 1 | AQ26: 1 | AR26: 1 | AS26: 1 | AU26: 1 | AV26: 1 | AW26: 1 | AX26: =SUM(AA26:AW26) -> 20 | AY26: =(AX26*$X26)+$Y26+$Z26 -> 3600 | AZ26: =$AZ$6*BU26 -> 1600 | BA26: 1 | BB26: 1 | BC26: 1 | BE26: 1 | BF26: 1 | BG26: 1 | BH26: 1 | BI26: 1 | BJ26: 1 | BL26: 1 | BM26: 1 | BN26: 1 | BP26: 1 | BQ26: 1 | BS26: 1 | BT26: 1 | BU26: =SUM(BA26:BT26) -> 16 | BV26: =(BU26*$X26)+$Y26+$AZ26 -> 4480
B27: 18 | C27: Precise | D27: 10 | E27: Dropfuse 200A | F27: PO2025060020 / QNT-2525-02635 | G27: 13800 | H27: K.Kowit | I27: 45850 | U27: 20 | V27: เจมส์(ฝึกงาน) | W27: 2160 | X27: 180 | Z27: =$Z$6*AX28 -> 1500 | AX27: =SUM(AA27:AW27) -> 0 | AZ27: =$AZ$6*BU27 -> 0 | BU27: =SUM(BA27:BT27) -> 0 | BV27: =(BU27*$X27)+$Y27+$AZ27 -> 0
B28: 19 | C28: บริษัท สุขี เครน จำกัด | D28: 30 | E28: ค่าซ่อมเกียร์ฝาก สาย PTO พร้อมก้ามปู น้ำมันเกียร์ | F28: BL2025060026 | G28: 11500 | H28: K.Kowit | I28: 45850 | U28: 21 | V28: นาย(ฝึกงาน) | W28: 1980 | X28: 180 | Z28: =$Z$6*AX29 -> 0 | AG28: 1 | AH28: 1 | AI28: 1 | AJ28: 1 | AK28: 1 | AL28: 1 | AN28: 1 | AO28: 1 | AP28: 1 | AQ28: 1 | AR28: 1 | AS28: 1 | AU28: 1 | AV28: 1 | AW28: 1 | AX28: =SUM(AA28:AW28) -> 15 | AY28: =(AX28*$X28)+$Y28+$Z28 -> 2700 | AZ28: =$AZ$6*BU28 -> 1600 | BA28: 1 | BB28: 1 | BC28: 1 | BE28: 1 | BF28: 1 | BG28: 1 | BH28: 1 | BI28: 1 | BJ28: 1 | BL28: 1 | BM28: 1 | BN28: 1 | BP28: 1 | BQ28: 1 | BS28: 1 | BT28: 1 | BU28: =SUM(BA28:BT28) -> 16 | BV28: =(BU28*$X28)+$Y28+$AZ28 -> 4480
B29: 20 | C29: บริษัท อรุณค้าเหล็ก จำกัด | D29: 10 | E29: เหล็กซีรางน้ำ 75มม. | F29: J680702015 | G29: 2310 | H29: K.Kowit | I29: 45850 | U29: 22 | V29: ดิว(ฝึกงาน) | W29: 1440 | X29: 180 | Z29: =$Z$6*AX30 -> 0 | AX29: =SUM(AA29:AW29) -> 0 | AZ29: =$AZ$6*BU29 -> 0 | BU29: =SUM(BA29:BT29) -> 0 | BV29: =(BU29*$X29)+$Y29+$AZ29 -> 0
B30: 21 | C30: บริษัท ไทยถาวรรุ่งโรจน์ จำกัด | D30: 10 | E30: ท่อน้ำ HDPE และข้อต่อ | G30: 799 | H30: K.Kowit | I30: 45850 | U30: 23 | V30: น็อต(ฝึกงาน) | W30: 2160 | X30: 180 | Z30: =$Z$6*AX31 -> 1500 | AX30: =SUM(AA30:AW30) -> 0 | AZ30: =$AZ$6*BU30 -> 0 | BU30: =SUM(BA30:BT30) -> 0 | BV30: =(BU30*$X30)+$Y30+$AZ30 -> 0
B31: 22 | C31: หจก. บีเอ็ม แอนด์ เบนซ์ ค้าวัสดุ (อยุธยา) | D31: 10 | E31: อุปกรณ์ทั่วไป เครื่องมือ | G31: 450 | H31: K.Kowit | I31: 45850 | U31: 24 | V31: อาม(ฝึกงาน) | W31: 1980 | X31: 180 | Z31: =$Z$6*AX32 -> 0 | AG31: 1 | AH31: 1 | AI31: 1 | AJ31: 1 | AK31: 1 | AL31: 1 | AN31: 1 | AO31: 1 | AP31: 1 | AQ31: 1 | AR31: 1 | AS31: 1 | AU31: 1 | AV31: 1 | AW31: 1 | AX31: =SUM(AA31:AW31) -> 15 | AY31: =(AX31*$X31)+$Y31+$Z31 -> 2700 | AZ31: =$AZ$6*BU31 -> 300 | BA31: 1 | BB31: 1 | BC31: 1 | BU31: =SUM(BA31:BT31) -> 3 | BV31: =(BU31*$X31)+$Y31+$AZ31 -> 840
B32: 23 | C32: หจก. บีเอ็ม แอนด์ เบนซ์ ค้าวัสดุ (อยุธยา) | D32: 10 | E32: อุปกรณ์ทั่วไป เครื่องมือ | G32: 320 | H32: K.Kowit | I32: 45850 | AY32: =SUM(AY8:AY31) -> 97170 | BV32: =SUM(BV8:BV31) -> 62716.667
B33: 24 | C33: ร้านขายของแถวบางคล้า | D33: 10 | E33: Snake guard | G33: 15000 | H33: K.Kowit | I33: 45850 | O33: 38060.938 | P33: 38060.938 | Q33: 2013814174 | R33: กสิกร (ถวิล)
B34: 25 | D34: 70 | E34: ค่าเลี้ยงข้าวลูกค้า | G34: 5610 | H34: K.Kowit | I34: 45850 | O34: 20268.75 | P34: 20268.75 | Q34: 1152673074 | R34: กสิกร(สิรภพ) | AY34: =AY32+BV32 -> 159886.67
B35: 26 | D35: 20 | E35: ค่าจ้างทีมงานเร่งด่วนสำหรับงานชัตดาวน์ | G35: 15000 | H35: K.Kowit | I35: ทำงานวันที่ 12/08/2025 | O35: 17275 | P35: 17275 | Q35: 1951329262 | R35: กสิกร (อดิศักดิ์)
B36: 27 | D36: 20 | E36: ค่า Setting Relay | G36: 5000 | H36: K.Kowit | I36: 45850 | O36: 6693.75 | P36: 6693.75 | Q36: 0461948944 | R36: กสิกร(ดำรงศักดิ์ นิวาสรัมย์)
B37: 28 | D37: 70 | E37: เลี้ยงปิดไซด์ | G37: 7000 | H37: K.Kowit | I37: 45850 | N37: 2 | O37: 6671.875 | P37: 13343.75 | Q37: 0893870970 | R37: กสิกร(นันทพร) แฟน
B38: 29 | C38: N.R.E | D38: 10 | E38: ค่าหางปลา และ กราวด์ Rod | G38: 3104.81 | H38: K.Kowit | I38: 45850 | N38: 2 | O38: 5322.5 | P38: 10645 | Q38: 0623566064 | R38: กสิกร (เกียรติยศ)
B39: 30 | C39: บริษัท พนัส เอ็นจิเนียร์ จำกัด (สำนักงานใหญ่) | D39: 10 | E39: สลิง 25 | G39: 4080 | H39: K.Kowit | I39: 45850 | N39: 2 | O39: 3315 | P39: 6630 | Q39: 2048224310 | R39: กสิกร (ศตวรรช)
